Workbook
Name annex1: #N/A
Name annex2: #N/A
Name Macrobond_Object1: '1 000'!$A$3:$B$264
Name Macrobond_Object1: '10 000'!$A$3:$B$264
Name Macrobond_Object1: '100 000'!$A$3:$B$264
Name Macrobond_Object1: '150 000'!$A$3:$B$264
Name Macrobond_Object1: '200 000'!$A$3:$B$264
Name Macrobond_Object1: '5 000'!$A$3:$B$264

Sheet Arkusz1
A1: System Podatkowy | B1: Wartość wstępna | C1: Zysk brutto | D1: Podatek | E1: Zysk netto | G1: portfel inwestycyjny | H1: 100000
A2: OKI | B2: =H2+H3 -> 100000 | C2: =H2*B11+H3*B12 -> 21224 | D2: =MAX(0, (B2+C2)-100000)*$B$7 + MAX(0, H3-25000)*$B$7 -> 614.2472 | E2: =C2-D2 -> 20609.753 | G2: akcje | H2: =H1*0.4 -> 40000
A3: Belka | B3: =H2+H3 -> 100000 | C3: =H2*B11+H3*B12 -> 21224 | D3: =C3*B6 -> 4032.56 | E3: =C3-D3 -> 17191.44 | G3: depozyty | H3: =0.6*H1 -> 60000
A6: Podatek Belka | B6: 0.19
A7: Podatek OKI | B7: =B6*B8 -> 0.010925
A8: Stopa ref. NBP 2025 | B8: 0.0575
A10: Stopy zwrotu
A11: WIG | B11: 0.4733 | C11: Tabela stóp zwrotu indeksów - Notowania - Puls Biznesu
A12: Średnie oprocentowanie nowo zakladanych depozytów za 2025 r. (NBP) | B12: 0.0382 | C12: Arkusz 2 OPN_PLN

Sheet 2 OPN_PLN
A1: Tabela 2. Średnie oprocentowanie nowych i renegocjowanych umów złotowych
B2: Sektor | C2: Kategoria | D2: Termin * | E2: nr | F2: fakt | G2: 38353 | H2: 38384 | I2: 38412 | J2: 38443 | K2: 38473 | L2: 38504 | M2: 38534 | N2: 38565 | O2: 38596 | P2: 38626 | Q2: 38657 | R2: 38687 | S2: 38718 | T2: 38749 | U2: 38777 | V2: 38808 | W2: 38838 | X2: 38869 | Y2: 38899 | Z2: 38930 | AA2: 38961 | AB2: 38991 | AC2: 39022 | AD2: 39052 | AE2: 39083 | AF2: 39114 | AG2: 39142 | AH2: 39173 | AI2: 39203 | AJ2: 39234 | AK2: 39264 | AL2: 39295 | AM2: 39326 | AN2: 39356 | AO2: 39387 | AP2: 39417 | AQ2: 39448 | AR2: 39479 | AS2: 39508 | AT2: 39539 | AU2: 39569 | AV2: 39600 | AW2: 39630 | AX2: 39661 | AY2: 39692 | AZ2: 39722 | BA2: 39753 | BB2: 39783 | BC2: 39814 | BD2: 39845 | BE2: 39873 | BF2: 39904 | BG2: 39934 | BH2: 39965 | BI2: 39995 | BJ2: 40026 | BK2: 40057 | BL2: 40087 | BM2: 40118 | BN2: 40148 | BO2: 40179 | BP2: 40210 | BQ2: 40238 | BR2: 40269 | BS2: 40299 | BT2: 40330 | BU2: 40360 | BV2: 40391 | BW2: 40422 | BX2: 40452 | BY2: 40483 | BZ2: 40513 | CA2: 40544 | CB2: 40575 | CC2: 40603 | CD2: 40634 | CE2: 40664 | CF2: 40695 | CG2: 40725 | CH2: 40756 | CI2: 40787 | CJ2: 40817 | CK2: 40848 | CL2: 40878 | CM2: 40909 | CN2: 40940 | CO2: 40969 | CP2: 41000 | CQ2: 41030 | CR2: 41061 | CS2: 41091 | CT2: 41122 | CU2: 41153 | CV2: 41183 | CW2: 41214 | CX2: 41244 | CY2: 41275 | CZ2: 41306 | DA2: 41334 | DB2: 41365 | DC2: 41395 | DD2: 41426 | DE2: 41456 | DF2: 41487 | DG2: 41518 | DH2: 41548 | DI2: 41579 | DJ2: 41609 | DK2: 41640 | DL2: 41671 | DM2: 41699 | DN2: 41730 | DO2: 41760 | DP2: 41791 | DQ2: 41821 | DR2: 41852 | DS2: 41883 | DT2: 41913 | DU2: 41944 | DV2: 41974 | DW2: 42005 | DX2: 42036 | DY2: 42064 | DZ2: 42095 | EA2: 42125 | EB2: 42156 | EC2: 42186 | ED2: 42217 | EE2: 42248 | EF2: 42278 | EG2: 42309 | EH2: 42339 | EI2: 42370 | EJ2: 42401 | EK2: 42430 | EL2: 42461 | EM2: 42491 | EN2: 42522 | EO2: 42552 | EP2: 42583 | EQ2: 42614 | ER2: 42644 | ES2: 42675 | ET2: 42705 | EU2: 42736 | EV2: 42767 | EW2: 42795 | EX2: 42826 | EY2: 42856 | EZ2: 42887 | FA2: 42917 | FB2: 42948 | FC2: 42979 | FD2: 43009 | FE2: 43040 | FF2: 43070 | FG2: 43101 | FH2: 43132 | FI2: 43160 | FJ2: 43191 | FK2: 43221 | FL2: 43252 | FM2: 43282 | FN2: 43313 | FO2: 43344 | FP2: 43374 | FQ2: 43405 | FR2: 43435 | FS2: 43466 | FT2: 43497 | FU2: 43525 | FV2: 43556 | FW2: 43586 | FX2: 43617 | FY2: 43647 | FZ2: 43678 | GA2: 43709 | GB2: 43739 | GC2: 43770 | GD2: 43800 | GE2: 43831 | GF2: 43862 | GG2: 43891 | GH2: 43922 | GI2: 43952 | GJ2: 43983 | GK2: 44013 | GL2: 44044 | GM2: 44075 | GN2: 44105 | GO2: 44136 | GP2: 44166 | GQ2: 44197 | GR2: 44228 | GS2: 44256 | GT2: 44287 | GU2: 44317 | GV2: 44348 | GW2: 44378 | GX2: 44409 | GY2: 44440 | GZ2: 44470 | HA2: 44501 | HB2: 44531 | HC2: 44562 | HD2: 44593 | HE2: 44621 | HF2: 44652 | HG2: 44682 | HH2: 44713 | HI2: 44743 | HJ2: 44774 | HK2: 44805 | HL2: 44835 | HM2: 44866 | HN2: 44896 | HO2: 44927 | HP2: 44958 | HQ2: 44986 | HR2: 45017 | HS2: 45047 | HT2: 45078 | HU2: 45108 | HV2: 45139 | HW2: 45170 | HX2: 45200 | HY2: 45231 | HZ2: 45261 | IA2: 45292 | IB2: 45323 | IC2: 45352 | ID2: 45383 | IE2: 45413 | IF2: 45444 | IG2: 45474 | IH2: 45505 | II2: 45536 | IJ2: 45566 | IK2: 45597 | IL2: 45627 | IM2: 45658 | IN2: 45689 | IO2: 45717 | IP2: 45748 | IQ2: 45778 | IR2: 45809 | IS2: 45839 | IT2: 45870 | IU2: 45901 | IV2: 45931 | IW2: 45962 | IX2: 45992 | IY2: 46023 | IZ2: 46054 | JA2: 46082 | JB2: 46113 | JC2: 46143 | JD2: 46174 | JE2: 46204
A3: Depozyty i inne zobowiązania w PLN | B3: Gospodarstwa domowe i instytucje niekomercyjne działające na rzecz gospodarstw domowych | C3: Depozyty z terminem pierwotnym | D3: do 1 miesiąca włącznie | E3: 1 | F3: M_7;AC:A,BCS:2250,BI:L22,BRS:S1,CT:PLN,DTM:R,F:M,IBC:N,MO:T06,RA:PL | G3: 0.0528 | H3: 0.0518 | I3: 0.0516 | J3: 0.0494 | K3: 0.0459 | L3: 0.0443 | M3: 0.0414 | N3: 0.0399 | O3: 0.0383 | P3: 0.0372 | Q3: 0.0374 | R3: 0.0362 | S3: 0.0371 | T3: 0.0361 | U3: 0.0334 | V3: 0.0339 | W3: 0.0332 | X3: 0.0335 | Y3: 0.0335 | Z3: 0.0336 | AA3: 0.0333 | AB3: 0.0339 | AC3: 0.0335 | AD3: 0.0333 | AE3: 0.0336 | AF3: 0.0341 | AG3: 0.034 | AH3: 0.0339 | AI3: 0.0354 | AJ3: 0.036 | AK3: 0.0375 | AL3: 0.0382 | AM3: 0.0395 | AN3: 0.0406 | AO3: 0.0409 | AP3: 0.041 | AQ3: 0.0432 | AR3: 0.046 | AS3: 0.0491 | AT3: 0.0514 | AU3: 0.0506 | AV3: 0.0519 | AW3: 0.0516 | AX3: 0.0526 | AY3: 0.0531 | AZ3: 0.0541 | BA3: 0.0539 | BB3: 0.0538 | BC3: 0.0524 | BD3: 0.0453 | BE3: 0.0411 | BF3: 0.0375 | BG3: 0.0353 | BH3: 0.035 | BI3: 0.0324 | BJ3: 0.0315 | BK3: 0.0312 | BL3: 0.0304 | BM3: 0.0303 | BN3: 0.0288 | BO3: 0.027 | BP3: 0.0273 | BQ3: 0.028 | BR3: 0.0275 | BS3: 0.0287 | BT3: 0.0288 | BU3: 0.0275 | BV3: 0.027 | BW3: 0.0276 | BX3: 0.0272 | BY3: 0.0273 | BZ3: 0.0265 | CA3: 0.0273 | CB3: 0.0288 | CC3: 0.0296 | CD3: 0.0306 | CE3: 0.0321 | CF3: 0.036 | CG3: 0.0369 | CH3: 0.0379 | CI3: 0.0379 | CJ3: 0.0383 | CK3: 0.0386 | CL3: 0.0392 | CM3: 0.0396 | CN3: 0.0388 | CO3: 0.0395 | CP3: 0.0364 | CQ3: 0.0372 | CR3: 0.0372 | CS3: 0.0357 | CT3: 0.0342 | CU3: 0.0354 | CV3: 0.0344 | CW3: 0.034 | CX3: 0.0321 | CY3: 0.0291 | CZ3: 0.0276 | DA3: 0.0249 | DB3: 0.023 | DC3: 0.0215 | DD3: 0.0206 | DE3: 0.0203 | DF3: 0.02 | DG3: 0.0215 | DH3: 0.0212 | DI3: 0.0212 | DJ3: 0.0216 | DK3: 0.022 | DL3: 0.0219 | DM3: 0.0222 | DN3: 0.0225 | DO3: 0.0226 | DP3: 0.0223 | DQ3: 0.0222 | DR3: 0.0224 | DS3: 0.0227 | DT3: 0.0199 | DU3: 0.0177 | DV3: 0.0217 | DW3: 0.0213 | DX3: 0.0211 | DY3: 0.0183 | DZ3: 0.0166 | EA3: 0.0146 | EB3: 0.0149 | EC3: 0.015 | ED3: 0.0153 | EE3: 0.0154 | EF3: 0.0151 | EG3: 0.0155 | EH3: 0.0154 | EI3: 0.0145 | EJ3: 0.0139 | EK3: 0.0139 | EL3: 0.0136 | EM3: 0.0131 | EN3: 0.0126 | EO3: 0.0129 | EP3: 0.0136 | EQ3: 0.0132 | ER3: 0.0127 | ES3: 0.0122 | ET3: 0.0112 | EU3: 0.012 | EV3: 0.0115 | EW3: 0.0115 | EX3: 0.0106 | EY3: 0.0102 | EZ3: 0.0101 | FA3: 0.0106 | FB3: 0.0104 | FC3: 0.0102 | FD3: 0.0109 | FE3: 0.0114 | FF3: 0.0119 | FG3: 0.0116 | FH3: 0.0108 | FI3: 0.0108 | FJ3: 0.0108 | FK3: 0.0107 | FL3: 0.0119 | FM3: 0.0121 | FN3: 0.0119 | FO3: 0.0164 | FP3: 0.0126 | FQ3: 0.011 | FR3: 0.0098 | FS3: 0.0102 | FT3: 0.0106 | FU3: 0.0085 | FV3: 0.0085 | FW3: 0.0087 | FX3: 0.0091 | FY3: 0.0088 | FZ3: 0.0085 | GA3: 0.0084 | GB3: 0.0084 | GC3: 0.0085 | GD3: 0.008 | GE3: 0.0082 | GF3: 0.008 | GG3: 0.007 | GH3: 0.0043 | GI3: 0.0036 | GJ3: 0.0022 | GK3: 0.0016 | GL3: 0.0018 | GM3: 0.0024 | GN3: 0.0023 | GO3: 0.0017 | GP3: 0.0013 | GQ3: 0.0013 | GR3: 0.0013 | GS3: 0.001 | GT3: 0.0013 | GU3: 0.0011 | GV3: 0.0012 | GW3: 0.0015 | GX3: 0.0014 | GY3: 0.0017 | GZ3: 0.002 | HA3: 0.0023 | HB3: 0.0029 | HC3: 0.0044 | HD3: 0.0063 | HE3: 0.009 | HF3: 0.0158 | HG3: 0.0308 | HH3: 0.0394 | HI3: 0.0406 | HJ3: 0.0414 | HK3: 0.045 | HL3: 0.0462 | HM3: 0.0577 | HN3: 0.062 | HO3: 0.0504 | HP3: 0.0482 | HQ3: 0.0493 | HR3: 0.05 | HS3: 0.0496 | HT3: 0.0508 | HU3: 0.0487 | HV3: 0.0493 | HW3: 0.0466 | HX3: 0.0435 | HY3: 0.0421 | HZ3: 0.0425 | IA3: 0.0433 | IB3: 0.0444 | IC3: 0.0437 | ID3: 0.0404 | IE3: 0.0405 | IF3: 0.0403 | IG3: 0.0401 | IH3: 0.0403 | II3: 0.0401 | IJ3: 0.0375 | IK3: 0.037 | IL3: 0.0363 | IM3: 0.0385 | IN3: 0.0375 | IO3: 0.038 | IP3: 0.0373 | IQ3: 0.0366 | IR3: 0.0355 | IS3: 0.0343 | IT3: 0.0337 | IU3: 0.0327 | IV3: 0.0323 | IW3: 0.0287 | IX3: 0.0271 | IY3: 0.0284 | IZ3: 0.0282 | JA3: 0.0277 | JB3: 0.0259 | JC3: 0.0262 | JD3: 0.0247 | JE3: 0.0263
D4: powyżej 1 miesiąca do 3 miesięcy włącznie | E4: 2 | F4: M_7;AC:A,BCS:2250,BI:L22,BRS:S1,CT:PLN,DTM:R,F:M,IBC:N,MO:T07,RA:PL | G4: 0.053 | H4: 0.0518 | I4: 0.0505 | J4: 0.047 | K4: 0.0429 | L4: 0.0412 | M4: 0.0375 | N4: 0.036 | O4: 0.0346 | P4: 0.0339 | Q4: 0.0342 | R4: 0.0343 | S4: 0.0344 | T4: 0.0319 | U4: 0.0313 | V4: 0.0315 | W4: 0.0314 | X4: 0.0343 | Y4: 0.034 | Z4: 0.0329 | AA4: 0.0329 | AB4: 0.0334 | AC4: 0.0342 | AD4: 0.0333 | AE4: 0.034 | AF4: 0.0327 | AG4: 0.0339 | AH4: 0.0341 | AI4: 0.0349 | AJ4: 0.0359 | AK4: 0.0394 | AL4: 0.0391 | AM4: 0.0403 | AN4: 0.0409 | AO4: 0.0417 | AP4: 0.0449 | AQ4: 0.0445 | AR4: 0.0464 | AS4: 0.0497 | AT4: 0.052 | AU4: 0.0543 | AV4: 0.0546 | AW4: 0.056 | AX4: 0.0593 | AY4: 0.0676 | AZ4: 0.0671 | BA4: 0.0691 | BB4: 0.0734 | BC4: 0.0695 | BD4: 0.0621 | BE4: 0.0566 | BF4: 0.0521 | BG4: 0.0525 | BH4: 0.0516 | BI4: 0.0505 | BJ4: 0.049 | BK4: 0.0487 | BL4: 0.0485 | BM4: 0.049 | BN4: 0.0485 | BO4: 0.0464 | BP4: 0.0459 | BQ4: 0.0466 | BR4: 0.0435 | BS4: 0.0442 | BT4: 0.0431 | BU4: 0.0422 | BV4: 0.0412 | BW4: 0.041 | BX4: 0.0402 | BY4: 0.0413 | BZ4: 0.042 | CA4: 0.0407 | CB4: 0.04 | CC4: 0.0422 | CD4: 0.0417 | CE4: 0.0426 | CF4: 0.046 | CG4: 0.0468 | CH4: 0.046 | CI4: 0.0457 | CJ4: 0.0474 | CK4: 0.0517 | CL4: 0.0535 | CM4: 0.0545 | CN4: 0.0539 | CO4: 0.0537 | CP4: 0.0539 | CQ4: 0.0556 | CR4: 0.0574 | CS4: 0.0558 | CT4: 0.0551 | CU4: 0.0541 | CV4: 0.054 | CW4: 0.0514 | CX4: 0.0485 | CY4: 0.0456 | CZ4: 0.0438 | DA4: 0.0398 | DB4: 0.0366 | DC4: 0.0343 | DD4: 0.0308 | DE4: 0.0287 | DF4: 0.0284 | DG4: 0.0277 | DH4: 0.0285 | DI4: 0.0283 | DJ4: 0.0276 | DK4: 0.0274 | DL4: 0.0276 | DM4: 0.0278 | DN4: 0.0281 | DO4: 0.028 | DP4: 0.0283 | DQ4: 0.0279 | DR4: 0.0278 | DS4: 0.0277 | DT4: 0.0272 | DU4: 0.0263 | DV4: 0.0252 | DW4: 0.0242 | DX4: 0.0248 | DY4: 0.0234 | DZ4: 0.0225 | EA4: 0.0208 | EB4: 0.0203 | EC4: 0.0202 | ED4: 0.0199 | EE4: 0.0193 | EF4: 0.0197 | EG4: 0.0195 | EH4: 0.0189 | EI4: 0.0189 | EJ4: 0.0185 | EK4: 0.018 | EL4: 0.0179 | EM4: 0.0177 | EN4: 0.0182 | EO4: 0.0195 | EP4: 0.0183 | EQ4: 0.0184 | ER4: 0.0188 | ES4: 0.0179 | ET4: 0.0168 | EU4: 0.0168 | EV4: 0.0165 | EW4: 0.0162 | EX4: 0.0162 | EY4: 0.0158 | EZ4: 0.0153 | FA4: 0.016 | FB4: 0.0162 | FC4: 0.0161 | FD4: 0.0173 | FE4: 0.0177 | FF4: 0.0172 | FG4: 0.0168 | FH4: 0.0167 | FI4: 0.0169 | FJ4: 0.0172 | FK4: 0.0185 | FL4: 0.0182 | FM4: 0.0175 | FN4: 0.0178 | FO4: 0.017 | FP4: 0.018 | FQ4: 0.0229 | FR4: 0.0222 | FS4: 0.0205 | FT4: 0.0199 | FU4: 0.0196 | FV4: 0.0195 | FW4: 0.0191 | FX4: 0.0167 | FY4: 0.0165 | FZ4: 0.016 | GA4: 0.0153 | GB4: 0.0156 | GC4: 0.0155 | GD4: 0.0137 | GE4: 0.0146 | GF4: 0.0141 | GG4: 0.0155 | GH4: 0.0129 | GI4: 0.0088 | GJ4: 0.0063 | GK4: 0.005 | GL4: 0.0046 | GM4: 0.0068 | GN4: 0.0055 | GO4: 0.0067 | GP4: 0.0074 | GQ4: 0.0044 | GR4: 0.0032 | GS4: 0.0024 | GT4: 0.0021 | GU4: 0.0027 | GV4: 0.0029 | GW4: 0.0026 | GX4: 0.0027 | GY4: 0.0033 | GZ4: 0.0042 | HA4: 0.0041 | HB4: 0.0064 | HC4: 0.0091 | HD4: 0.0101 | HE4: 0.015 | HF4: 0.0189 | HG4: 0.0326 | HH4: 0.0458 | HI4: 0.0501 | HJ4: 0.0522 | HK4: 0.0556 | HL4: 0.0591 | HM4: 0.0617 | HN4: 0.0627 | HO4: 0.0624 | HP4: 0.0614 | HQ4: 0.0603 | HR4: 0.0583 | HS4: 0.058 | HT4: 0.0555 | HU4: 0.0557 | HV4: 0.0505 | HW4: 0.0478 | HX4: 0.0446 | HY4: 0.0439 | HZ4: 0.043 | IA4: 0.0427 | IB4: 0.0422 | IC4: 0.0419 | ID4: 0.0408 | IE4: 0.0403 | IF4: 0.0407 | IG4: 0.0408 | IH4: 0.0397 | II4: 0.0399 | IJ4: 0.0395 | IK4: 0.0393 | IL4: 0.0392 | IM4: 0.0404 | IN4: 0.0401 | IO4: 0.0404 | IP4: 0.0406 | IQ4: 0.0398 | IR4: 0.0389 | IS4: 0.0387 | IT4: 0.0385 | IU4: 0.0369 | IV4: 0.0361 | IW4: 0.0352 | IX4: 0.0345 | IY4: 0.0336 | IZ4: 0.0327 | JA4: 0.0317 | JB4: 0.0304 | JC4: 0.0305 | JD4: 0.0305 | JE4: 0.0305
D5: powyżej 3 miesięcy do 6 miesięcy włącznie | E5: 3 | F5: M_7;AC:A,BCS:2250,BI:L22,BRS:S1,CT:PLN,DTM:R,F:M,IBC:N,MO:T08,RA:PL | G5: 0.0542 | H5: 0.053 | I5: 0.0484 | J5: 0.0454 | K5: 0.0416 | L5: 0.0426 | M5: 0.0378 | N5: 0.0351 | O5: 0.0357 | P5: 0.0354 | Q5: 0.0327 | R5: 0.0331 | S5: 0.0325 | T5: 0.0298 | U5: 0.0281 | V5: 0.0303 | W5: 0.0289 | X5: 0.0285 | Y5: 0.0295 | Z5: 0.0301 | AA5: 0.0331 | AB5: 0.0325 | AC5: 0.0301 | AD5: 0.0306 | AE5: 0.0328 | AF5: 0.0346 | AG5: 0.0308 | AH5: 0.0311 | AI5: 0.0319 | AJ5: 0.0328 | AK5: 0.036 | AL5: 0.0356 | AM5: 0.0362 | AN5: 0.0384 | AO5: 0.0404 | AP5: 0.0427 | AQ5: 0.0435 | AR5: 0.0463 | AS5: 0.0493 | AT5: 0.0506 | AU5: 0.0522 | AV5: 0.0545 | AW5: 0.0555 | AX5: 0.0562 | AY5: 0.0557 | AZ5: 0.0655 | BA5: 0.0725 | BB5: 0.0713 | BC5: 0.0686 | BD5: 0.0618 | BE5: 0.0565 | BF5: 0.0528 | BG5: 0.0526 | BH5: 0.0518 | BI5: 0.0521 | BJ5: 0.0518 | BK5: 0.051 | BL5: 0.0507 | BM5: 0.0512 | BN5: 0.0496 | BO5: 0.0475 | BP5: 0.0478 | BQ5: 0.0459 | BR5: 0.0456 | BS5: 0.0441 | BT5: 0.0425 | BU5: 0.0416 | BV5: 0.0419 | BW5: 0.0414 | BX5: 0.0421 | BY5: 0.0423 | BZ5: 0.0428 | CA5: 0.0424 | CB5: 0.0434 | CC5: 0.0434 | CD5: 0.0439 | CE5: 0.044 | CF5: 0.0442 | CG5: 0.0456 | CH5: 0.0472 | CI5: 0.0471 | CJ5: 0.0499 | CK5: 0.0493 | CL5: 0.0487 | CM5: 0.0533 | CN5: 0.0537 | CO5: 0.0511 | CP5: 0.0504 | CQ5: 0.0518 | CR5: 0.0548 | CS5: 0.0557 | CT5: 0.055 | CU5: 0.0544 | CV5: 0.054 | CW5: 0.0509 | CX5: 0.0496 | CY5: 0.0461 | CZ5: 0.0437 | DA5: 0.0366 | DB5: 0.034 | DC5: 0.0298 | DD5: 0.0273 | DE5: 0.0258 | DF5: 0.0249 | DG5: 0.0266 | DH5: 0.0277 | DI5: 0.028 | DJ5: 0.0279 | DK5: 0.0277 | DL5: 0.0276 | DM5: 0.0273 | DN5: 0.0279 | DO5: 0.0276 | DP5: 0.0273 | DQ5: 0.0281 | DR5: 0.0305 | DS5: 0.0324 | DT5: 0.0278 | DU5: 0.0238 | DV5: 0.0236 | DW5: 0.0223 | DX5: 0.0219 | DY5: 0.0208 | DZ5: 0.0177 | EA5: 0.0182 | EB5: 0.0164 | EC5: 0.0172 | ED5: 0.0173 | EE5: 0.0182 | EF5: 0.0178 | EG5: 0.0186 | EH5: 0.0185 | EI5: 0.0179 | EJ5: 0.0177 | EK5: 0.0165 | EL5: 0.0156 | EM5: 0.0151 | EN5: 0.015 | EO5: 0.0179 | EP5: 0.0169 | EQ5: 0.0171 | ER5: 0.0168 | ES5: 0.0163 | ET5: 0.016 | EU5: 0.0165 | EV5: 0.0166 | EW5: 0.0161 | EX5: 0.0159 | EY5: 0.0154 | EZ5: 0.0157 | FA5: 0.0166 | FB5: 0.0178 | FC5: 0.0172 | FD5: 0.0161 | FE5: 0.0163 | FF5: 0.0165 | FG5: 0.0194 | FH5: 0.0187 | FI5: 0.0181 | FJ5: 0.0178 | FK5: 0.0189 | FL5: 0.0182 | FM5: 0.0185 | FN5: 0.0178 | FO5: 0.017 | FP5: 0.0175 | FQ5: 0.0181 | FR5: 0.0223 | FS5: 0.0219 | FT5: 0.021 | FU5: 0.0168 | FV5: 0.016 | FW5: 0.015 | FX5: 0.0142 | FY5: 0.0144 | FZ5: 0.0137 | GA5: 0.0144 | GB5: 0.0144 | GC5: 0.0137 | GD5: 0.0136 | GE5: 0.0136 | GF5: 0.0133 | GG5: 0.0118 | GH5: 0.008 | GI5: 0.0056 | GJ5: 0.0037 | GK5: 0.0031 | GL5: 0.0023 | GM5: 0.0046 | GN5: 0.0044 | GO5: 0.0018 | GP5: 0.0021 | GQ5: 0.0026 | GR5: 0.0026 | GS5: 0.0021 | GT5: 0.0018 | GU5: 0.0015 | GV5: 0.0013 | GW5: 0.002 | GX5: 0.0018 | GY5: 0.0032 | GZ5: 0.0029 | HA5: 0.0059 | HB5: 0.0091 | HC5: 0.0115 | HD5: 0.015 | HE5: 0.0172 | HF5: 0.0243 | HG5: 0.0375 | HH5: 0.0475 | HI5: 0.0546 | HJ5: 0.059 | HK5: 0.0617 | HL5: 0.0598 | HM5: 0.0612 | HN5: 0.0636 | HO5: 0.0639 | HP5: 0.0585 | HQ5: 0.0582 | HR5: 0.0601 | HS5: 0.0597 | HT5: 0.0667 | HU5: 0.0581 | HV5: 0.057 | HW5: 0.0539 | HX5: 0.0512 | HY5: 0.0502 | HZ5: 0.048 | IA5: 0.0482 | IB5: 0.0473 | IC5: 0.0448 | ID5: 0.046 | IE5: 0.0448 | IF5: 0.0438 | IG5: 0.044 | IH5: 0.0439 | II5: 0.0425 | IJ5: 0.0427 | IK5: 0.0423 | IL5: 0.0429 | IM5: 0.0431 | IN5: 0.0431 | IO5: 0.0432 | IP5: 0.0427 | IQ5: 0.0418 | IR5: 0.0395 | IS5: 0.0394 | IT5: 0.038 | IU5: 0.0366 | IV5: 0.0363 | IW5: 0.0367 | IX5: 0.0348 | IY5: 0.0343 | IZ5: 0.0343 | JA5: 0.0298 | JB5: 0.0317 | JC5: 0.0287 | JD5: 0.0298 | JE5: 0.0309
D6: powyżej 6 miesięcy do 1 roku włącznie | E6: 4 | F6: M_7;AC:A,BCS:2250,BI:L22,BRS:S1,CT:PLN,DTM:R,F:M,IBC:N,MO:T10,RA:PL | G6: 0.0519 | H6: 0.048 | I6: 0.0498 | J6: 0.0321 | K6: 0.0396 | L6: 0.0396 | M6: 0.0366 | N6: 0.0406 | O6: 0.0367 | P6: 0.032 | Q6: 0.0327 | R6: 0.0367 | S6: 0.037 | T6: 0.0312 | U6: 0.0314 | V6: 0.0366 | W6: 0.0338 | X6: 0.0323 | Y6: 0.0333 | Z6: 0.0291 | AA6: 0.031 | AB6: 0.0345 | AC6: 0.0331 | AD6: 0.0326 | AE6: 0.0354 | AF6: 0.0334 | AG6: 0.0385 | AH6: 0.032 | AI6: 0.0316 | AJ6: 0.0328 | AK6: 0.036 | AL6: 0.0363 | AM6: 0.039 | AN6: 0.0377 | AO6: 0.0359 | AP6: 0.0374 | AQ6: 0.0382 | AR6: 0.0527 | AS6: 0.0451 | AT6: 0.0463 | AU6: 0.0515 | AV6: 0.0524 | AW6: 0.0491 | AX6: 0.0496 | AY6: 0.0493 | AZ6: 0.0585 | BA6: 0.0626 | BB6: 0.0696 | BC6: 0.0589 | BD6: 0.0538 | BE6: 0.0523 | BF6: 0.047 | BG6: 0.0478 | BH6: 0.0501 | BI6: 0.0488 | BJ6: 0.0505 | BK6: 0.047 | BL6: 0.047 | BM6: 0.0462 | BN6: 0.0458 | BO6: 0.0425 | BP6: 0.0431 | BQ6: 0.0439 | BR6: 0.044 | BS6: 0.0438 | BT6: 0.0439 | BU6: 0.0425 | BV6: 0.0425 | BW6: 0.0419 | BX6: 0.0416 | BY6: 0.0419 | BZ6: 0.0415 | CA6: 0.0402 | CB6: 0.0409 | CC6: 0.0422 | CD6: 0.0418 | CE6: 0.0416 | CF6: 0.0422 | CG6: 0.0422 | CH6: 0.0436 | CI6: 0.044 | CJ6: 0.0438 | CK6: 0.0436 | CL6: 0.0445 | CM6: 0.0403 | CN6: 0.04 | CO6: 0.0421 | CP6: 0.0418 | CQ6: 0.0438 | CR6: 0.0494 | CS6: 0.0498 | CT6: 0.0491 | CU6: 0.0494 | CV6: 0.049 | CW6: 0.045 | CX6: 0.0433 | CY6: 0.0406 | CZ6: 0.0384 | DA6: 0.0353 | DB6: 0.0326 | DC6: 0.03 | DD6: 0.0253 | DE6: 0.0247 | DF6: 0.0231 | DG6: 0.0246 | DH6: 0.0239 | DI6: 0.0263 | DJ6: 0.0276 | DK6: 0.0257 | DL6: 0.0256 | DM6: 0.0265 | DN6: 0.0279 | DO6: 0.028 | DP6: 0.0279 | DQ6: 0.0283 | DR6: 0.028 | DS6: 0.0272 | DT6: 0.0239 | DU6: 0.0213 | DV6: 0.02 | DW6: 0.0228 | DX6: 0.0243 | DY6: 0.0212 | DZ6: 0.0186 | EA6: 0.0182 | EB6: 0.0203 | EC6: 0.0195 | ED6: 0.0189 | EE6: 0.017 | EF6: 0.0191 | EG6: 0.0192 | EH6: 0.0192 | EI6: 0.0185 | EJ6: 0.0183 | EK6: 0.0179 | EL6: 0.0178 | EM6: 0.0177 | EN6: 0.0174 | EO6: 0.018 | EP6: 0.0178 | EQ6: 0.0178 | ER6: 0.0179 | ES6: 0.017 | ET6: 0.0165 | EU6: 0.0165 | EV6: 0.0162 | EW6: 0.016 | EX6: 0.0162 | EY6: 0.0158 | EZ6: 0.0156 | FA6: 0.0161 | FB6: 0.0166 | FC6: 0.0164 | FD6: 0.0166 | FE6: 0.0167 | FF6: 0.0165 | FG6: 0.0164 | FH6: 0.0165 | FI6: 0.0172 | FJ6: 0.0171 | FK6: 0.0173 | FL6: 0.0175 | FM6: 0.0174 | FN6: 0.0171 | FO6: 0.0168 | FP6: 0.0165 | FQ6: 0.0166 | FR6: 0.0162 | FS6: 0.0166 | FT6: 0.0169 | FU6: 0.0162 | FV6: 0.0171 | FW6: 0.0163 | FX6: 0.0161 | FY6: 0.0159 | FZ6: 0.0152 | GA6: 0.0154 | GB6: 0.0153 | GC6: 0.0148 | GD6: 0.0149 | GE6: 0.0146 | GF6: 0.0141 | GG6: 0.0124 | GH6: 0.0078 | GI6: 0.0041 | GJ6: 0.0026 | GK6: 0.002 | GL6: 0.0014 | GM6: 0.0016 | GN6: 0.0015 | GO6: 0.0017 | GP6: 0.0016 | GQ6: 0.0016 | GR6: 0.0014 | GS6: 0.0014 | GT6: 0.0016 | GU6: 0.0014 | GV6: 0.0012 | GW6: 0.0013 | GX6: 0.0013 | GY6: 0.0017 | GZ6: 0.0024 | HA6: 0.0078 | HB6: 0.0127 | HC6: 0.0171 | HD6: 0.0189 | HE6: 0.0185 | HF6: 0.0251 | HG6: 0.0356 | HH6: 0.0463 | HI6: 0.0519 | HJ6: 0.0577 | HK6: 0.0628 | HL6: 0.0643 | HM6: 0.0678 | HN6: 0.0654 | HO6: 0.0636 | HP6: 0.0612 | HQ6: 0.0589 | HR6: 0.0574 | HS6: 0.0571 | HT6: 0.058 | HU6: 0.0586 | HV6: 0.0575 | HW6: 0.0541 | HX6: 0.0497 | HY6: 0.0466 | HZ6: 0.0457 | IA6: 0.043 | IB6: 0.0434 | IC6: 0.0431 | ID6: 0.0408 | IE6: 0.0429 | IF6: 0.0406 | IG6: 0.0427 | IH6: 0.0418 | II6: 0.0417 | IJ6: 0.0408 | IK6: 0.0405 | IL6: 0.0393 | IM6: 0.0402 | IN6: 0.0403 | IO6: 0.0386 | IP6: 0.0388 | IQ6: 0.0351 | IR6: 0.0343 | IS6: 0.035 | IT6: 0.0339 | IU6: 0.0351 | IV6: 0.0355 | IW6: 0.0326 | IX6: 0.0311 | IY6: 0.0308 | IZ6: 0.0285 | JA6: 0.0291 | JB6: 0.0282 | JC6: 0.03 | JD6: 0.0281 | JE6: 0.0303
D7: powyżej 1 roku | E7: 5 | F7: M_7;AC:A,BCS:2250,BI:L22,BRS:S1,CT:PLN,DTM:R,F:M,IBC:N,MO:K,RA:PL | G7: 0.0529 | H7: 0.0522 | I7: 0.0479 | J7: 0.0499 | K7: 0.0463 | L7: 0.0413 | M7: 0.0396 | N7: 0.0335 | O7: 0.0364 | P7: 0.0399 | Q7: 0.0496 | R7: 0.0526 | S7: 0.046 | T7: 0.0407 | U7: 0.0414 | V7: 0.0398 | W7: 0.0335 | X7: 0.0374 | Y7: 0.035 | Z7: 0.0311 | AA7: 0.0334 | AB7: 0.0162 | AC7: 0.0306 | AD7: 0.0286 | AE7: 0.0316 | AF7: 0.0243 | AG7: 0.0332 | AH7: 0.0325 | AI7: 0.0382 | AJ7: 0.0328 | AK7: 0.032 | AL7: 0.0358 | AM7: 0.0449 | AN7: 0.028 | AO7: 0.0364 | AP7: 0.0403 | AQ7: 0.0445 | AR7: 0.0377 | AS7: 0.03 | AT7: 0.0238 | AU7: 0.015 | AV7: 0.0183 | AW7: 0.0241 | AX7: 0.0207 | AY7: 0.066 | AZ7: 0.0683 | BA7: 0.0681 | BB7: 0.0678 | BC7: 0.0719 | BD7: 0.0522 | BE7: 0.0397 | BF7: 0.0343 | BG7: 0.0305 | BH7: 0.0308 | BI7: 0.0332 | BJ7: 0.0362 | BK7: 0.0399 | BL7: 0.0453 | BM7: 0.0454 | BN7: 0.0368 | BO7: 0.0405 | BP7: 0.0437 | BQ7: 0.0471 | BR7: 0.0459 | BS7: 0.0452 | BT7: 0.0446 | BU7: 0.0396 | BV7: 0.0386 | BW7: 0.039 | BX7: 0.0313 | BY7: 0.0393 | BZ7: 0.0425 | CA7: 0.0394 | CB7: 0.0416 | CC7: 0.0444 | CD7: 0.0408 | CE7: 0.0417 | CF7: 0.0436 | CG7: 0.043 | CH7: 0.0422 | CI7: 0.0427 | CJ7: 0.0435 | CK7: 0.0423 | CL7: 0.0435 | CM7: 0.0416 | CN7: 0.0429 | CO7: 0.0453 | CP7: 0.0484 | CQ7: 0.05 | CR7: 0.0509 | CS7: 0.0534 | CT7: 0.0465 | CU7: 0.0466 | CV7: 0.0435 | CW7: 0.0485 | CX7: 0.0423 | CY7: 0.0424 | CZ7: 0.0392 | DA7: 0.0353 | DB7: np. | DC7: np. | DD7: 0.0286 | DE7: np. | DF7: 0.0241 | DG7: 0.026 | DH7: 0.0254 | DI7: 0.0258 | DJ7: 0.0273 | DK7: np. | DL7: np. | DM7: np. | DN7: np. | DO7: np. | DP7: np. | DQ7: np. | DR7: 0.0246 | DS7: 0.0243 | DT7: 0.0229 | DU7: 0.0203 | DV7: 0.0228 | DW7: 0.0219 | DX7: 0.0232 | DY7: 0.0225 | DZ7: 0.0167 | EA7: 0.0176 | EB7: 0.0168 | EC7: 0.0171 | ED7: 0.0173 | EE7: 0.0177 | EF7: 0.0176 | EG7: 0.0174 | EH7: 0.0179 | EI7: 0.017 | EJ7: 0.017 | EK7: 0.0146 | EL7: 0.0135 | EM7: 0.0136 | EN7: 0.0119 | EO7: 0.0146 | EP7: 0.0128 | EQ7: 0.0154 | ER7: 0.0129 | ES7: 0.0141 | ET7: 0.0166 | EU7: 0.0131 | EV7: 0.0168 | EW7: 0.0161 | EX7: 0.0151 | EY7: 0.0142 | EZ7: 0.0134 | FA7: 0.0118 | FB7: 0.0126 | FC7: 0.0143 | FD7: 0.012 | FE7: 0.0119 | FF7: 0.0149 | FG7: 0.0141 | FH7: 0.0141 | FI7: 0.0149 | FJ7: 0.0167 | FK7: 0.0185 | FL7: 0.0183 | FM7: 0.0172 | FN7: 0.0158 | FO7: 0.0165 | FP7: 0.0162 | FQ7: 0.016 | FR7: 0.0174 | FS7: 0.013 | FT7: 0.0155 | FU7: 0.0172 | FV7: 0.0154 | FW7: 0.0158 | FX7: 0.0169 | FY7: 0.0162 | FZ7: 0.0176 | GA7: 0.0164 | GB7: 0.0158 | GC7: 0.0157 | GD7: 0.0146 | GE7: 0.0129 | GF7: 0.0136 | GG7: 0.0134 | GH7: 0.0079 | GI7: 0.0038 | GJ7: 0.0027 | GK7: 0.0015 | GL7: 0.0009 | GM7: 0.0018 | GN7: 0.0017 | GO7: 0.0028 | GP7: 0.0031 | GQ7: np. | GR7: 0.0029 | GS7: 0.0029 | GT7: 0.0014 | GU7: 0.0014 | GV7: 0.0009 | GW7: 0.0029 | GX7: 0.0029 | GY7: 0.0032 | GZ7: 0.0045 | HA7: 0.0033 | HB7: np. | HC7: 0.0216 | HD7: 0.0107 | HE7: 0.0237 | HF7: 0.0185 | HG7: 0.0437 | HH7: 0.0538 | HI7: np. | HJ7: 0.036 | HK7: np. | HL7: np. | HM7: np. | HN7: np. | HO7: np. | HP7: 0.042 | HQ7: 0.0546 | HR7: 0.0491 | HS7: 0.0493 | HT7: 0.0506 | HU7: 0.0494 | HV7: 0.0502 | HW7: 0.0468 | HX7: 0.0386 | HY7: 0.0375 | HZ7: 0.0408 | IA7: 0.0413 | IB7: 0.0269 | IC7: 0.027 | ID7: 0.0242 | IE7: 0.0323 | IF7: 0.0283 | IG7: 0.0277 | IH7: 0.0274 | II7: 0.031 | IJ7: np. | IK7: np. | IL7: 0.0273 | IM7: 0.0314 | IN7: 0.0351 | IO7: 0.0297 | IP7: np. | IQ7: 0.0325 | IR7: 0.0307 | IS7: np. | IT7: 0.0313 | IU7: 0.0278 | IV7: np. | IW7: 0.0248 | IX7: 0.0266 | IY7: 0.0252 | IZ7: 0.0227 | JA7: np. | JB7: np. | JC7: 0.019 | JD7: 0.0192 | JE7: 0.0277
D8: ogółem | E8: 6 | F8: M_7;AC:A,BCS:2250,BI:L22,BRS:S1,CT:PLN,DTM:R,F:M,IBC:N,MO:A,RA:PL | G8: 0.053 | H8: 0.0518 | I8: 0.0511 | J8: 0.0477 | K8: 0.0447 | L8: 0.0433 | M8: 0.0399 | N8: 0.0388 | O8: 0.0373 | P8: 0.0362 | Q8: 0.0366 | R8: 0.036 | S8: 0.0364 | T8: 0.0351 | U8: 0.0328 | V8: 0.0335 | W8: 0.0327 | X8: 0.0334 | Y8: 0.0335 | Z8: 0.0332 | AA8: 0.0331 | AB8: 0.0338 | AC8: 0.0335 | AD8: 0.0331 | AE8: 0.0337 | AF8: 0.0339 | AG8: 0.034 | AH8: 0.0338 | AI8: 0.0351 | AJ8: 0.0358 | AK8: 0.0378 | AL8: 0.0382 | AM8: 0.0395 | AN8: 0.0403 | AO8: 0.0406 | AP8: 0.0416 | AQ8: 0.0431 | AR8: 0.0469 | AS8: 0.0489 | AT8: 0.051 | AU8: 0.051 | AV8: 0.0523 | AW8: 0.0522 | AX8: 0.0539 | AY8: 0.0582 | AZ8: 0.0611 | BA8: 0.0623 | BB8: 0.0652 | BC8: 0.0615 | BD8: 0.0539 | BE8: 0.0496 | BF8: 0.0449 | BG8: 0.0448 | BH8: 0.044 | BI8: 0.0431 | BJ8: 0.0424 | BK8: 0.0424 | BL8: 0.0425 | BM8: 0.0421 | BN8: 0.0403 | BO8: 0.0391 | BP8: 0.0381 | BQ8: 0.039 | BR8: 0.039 | BS8: 0.0381 | BT8: 0.0368 | BU8: 0.0359 | BV8: 0.0352 | BW8: 0.0354 | BX8: 0.0353 | BY8: 0.0357 | BZ8: 0.0356 | CA8: 0.0356 | CB8: 0.0365 | CC8: 0.0377 | CD8: 0.0377 | CE8: 0.0384 | CF8: 0.0411 | CG8: 0.0424 | CH8: 0.0433 | CI8: 0.0436 | CJ8: 0.0447 | CK8: 0.0463 | CL8: 0.0473 | CM8: 0.0477 | CN8: 0.0466 | CO8: 0.0458 | CP8: 0.0458 | CQ8: 0.0468 | CR8: 0.0494 | CS8: 0.0492 | CT8: 0.0482 | CU8: 0.0478 | CV8: 0.0477 | CW8: 0.0449 | CX8: 0.0422 | CY8: 0.0396 | CZ8: 0.0375 | DA8: 0.0334 | DB8: 0.031 | DC8: 0.0281 | DD8: 0.0256 | DE8: 0.0247 | DF8: 0.0242 | DG8: 0.025 | DH8: 0.0255 | DI8: 0.0256 | DJ8: 0.0259 | DK8: 0.0255 | DL8: 0.0258 | DM8: 0.0261 | DN8: 0.0264 | DO8: 0.0263 | DP8: 0.0262 | DQ8: 0.0263 | DR8: 0.027 | DS8: 0.0278 | DT8: 0.025 | DU8: 0.0223 | DV8: 0.0231 | DW8: 0.0225 | DX8: 0.0227 | DY8: 0.0209 | DZ8: 0.0191 | EA8: 0.0178 | EB8: 0.0174 | EC8: 0.0177 | ED8: 0.0175 | EE8: 0.0174 | EF8: 0.0175 | EG8: 0.0177 | EH8: 0.0176 | EI8: 0.0171 | EJ8: 0.0167 | EK8: 0.0161 | EL8: 0.0157 | EM8: 0.0153 | EN8: 0.0152 | EO8: 0.0168 | EP8: 0.0161 | EQ8: 0.0163 | ER8: 0.0162 | ES8: 0.0156 | ET8: 0.0149 | EU8: 0.015 | EV8: 0.015 | EW8: 0.0147 | EX8: 0.0144 | EY8: 0.014 | EZ8: 0.0138 | FA8: 0.0144 | FB8: 0.0149 | FC8: 0.0146 | FD8: 0.0149 | FE8: 0.0152 | FF8: 0.0152 | FG8: 0.0158 | FH8: 0.0153 | FI8: 0.0153 | FJ8: 0.0153 | FK8: 0.016 | FL8: 0.0162 | FM8: 0.0161 | FN8: 0.0158 | FO8: 0.0168 | FP8: 0.0161 | FQ8: 0.018 | FR8: 0.0183 | FS8: 0.0175 | FT8: 0.0173 | FU8: 0.0159 | FV8: 0.0156 | FW8: 0.0152 | FX8: 0.0141 | FY8: 0.0141 | FZ8: 0.0134 | GA8: 0.0132 | GB8: 0.0134 | GC8: 0.0131 | GD8: 0.0121 | GE8: 0.0125 | GF8: 0.012 | GG8: 0.0121 | GH8: 0.0093 | GI8: 0.0062 | GJ8: 0.0044 | GK8: 0.0036 | GL8: 0.0032 | GM8: 0.0049 | GN8: 0.0042 | GO8: 0.0044 | GP8: 0.0051 | GQ8: 0.0042 | GR8: 0.0026 | GS8: 0.002 | GT8: 0.0018 | GU8: 0.0021 | GV8: 0.0022 | GW8: 0.0022 | GX8: 0.0023 | GY8: 0.0029 | GZ8: 0.0035 | HA8: 0.0044 | HB8: 0.0068 | HC8: 0.0102 | HD8: 0.0119 | HE8: 0.015 | HF8: 0.0203 | HG8: 0.0342 | HH8: 0.0455 | HI8: 0.049 | HJ8: 0.0525 | HK8: 0.0556 | HL8: 0.0568 | HM8: 0.0607 | HN8: 0.0625 | HO8: 0.0604 | HP8: 0.0581 | HQ8: 0.0576 | HR8: 0.057 | HS8: 0.0568 | HT8: 0.058 | HU8: 0.0553 | HV8: 0.0528 | HW8: 0.0496 | HX8: 0.0461 | HY8: 0.045 | HZ8: 0.0441 | IA8: 0.0442 | IB8: 0.0438 | IC8: 0.043 | ID8: 0.0418 | IE8: 0.0414 | IF8: 0.0412 | IG8: 0.0414 | IH8: 0.0408 | II8: 0.0406 | IJ8: 0.04 | IK8: 0.0396 | IL8: 0.0395 | IM8: 0.0407 | IN8: 0.0404 | IO8: 0.0405 | IP8: 0.0405 | IQ8: 0.0393 | IR8: 0.0382 | IS8: 0.0379 | IT8: 0.0373 | IU8: 0.0361 | IV8: 0.0356 | IW8: 0.0346 | IX8: 0.0334 | IY8: 0.0329 | IZ8: 0.0321 | JA8: 0.0307 | JB8: 0.0298 | JC8: 0.0294 | JD8: 0.0294 | JE8: 0.03
B9: Przedsiębiorstwa niefinansowe | C9: Depozyty z terminem pierwotnym | D9: do 1 miesiąca włącznie | E9: 7 | F9: M_7;AC:A,BCS:2240,BI:L22,BRS:S1,CT:PLN,DTM:R,F:M,IBC:N,MO:T06,RA:PL | G9: 0.0566 | H9: 0.0549 | I9: 0.0572 | J9: 0.0523 | K9: 0.0482 | L9: 0.046 | M9: 0.0434 | N9: 0.0417 | O9: 0.0404 | P9: 0.0402 | Q9: 0.0399 | R9: 0.0376 | S9: 0.039 | T9: 0.0373 | U9: 0.0358 | V9: 0.0356 | W9: 0.0359 | X9: 0.0352 | Y9: 0.0358 | Z9: 0.0356 | AA9: 0.0352 | AB9: 0.0359 | AC9: 0.0352 | AD9: 0.0348 | AE9: 0.0353 | AF9: 0.0357 | AG9: 0.0357 | AH9: 0.0352 | AI9: 0.0385 | AJ9: 0.0394 | AK9: 0.0411 | AL9: 0.0409 | AM9: 0.0422 | AN9: 0.045 | AO9: 0.0457 | AP9: 0.0418 | AQ9: 0.0471 | AR9: 0.0496 | AS9: 0.0529 | AT9: 0.055 | AU9: 0.0534 | AV9: 0.0551 | AW9: 0.0556 | AX9: 0.0562 | AY9: 0.0551 | AZ9: 0.0561 | BA9: 0.0541 | BB9: 0.0547 | BC9: 0.0475 | BD9: 0.0386 | BE9: 0.0324 | BF9: 0.0314 | BG9: 0.0329 | BH9: 0.0312 | BI9: 0.0288 | BJ9: 0.0279 | BK9: 0.0283 | BL9: 0.0278 | BM9: 0.029 | BN9: 0.0277 | BO9: 0.0266 | BP9: 0.0273 | BQ9: 0.0277 | BR9: 0.0282 | BS9: 0.0293 | BT9: 0.0295 | BU9: 0.0275 | BV9: 0.0291 | BW9: 0.0295 | BX9: 0.0296 | BY9: 0.0288 | BZ9: 0.0289 | CA9: 0.0284 | CB9: 0.0302 | CC9: 0.0321 | CD9: 0.0331 | CE9: 0.0333 | CF9: 0.0382 | CG9: 0.0387 | CH9: 0.0395 | CI9: 0.0399 | CJ9: 0.0391 | CK9: 0.0404 | CL9: 0.0396 | CM9: 0.0388 | CN9: 0.0383 | CO9: 0.0397 | CP9: 0.0392 | CQ9: 0.042 | CR9: 0.0424 | CS9: 0.0427 | CT9: 0.0432 | CU9: 0.0442 | CV9: 0.0425 | CW9: 0.0416 | CX9: 0.0381 | CY9: 0.0349 | CZ9: 0.0337 | DA9: 0.0299 | DB9: 0.0281 | DC9: 0.0266 | DD9: 0.0241 | DE9: 0.0216 | DF9: 0.0219 | DG9: 0.0224 | DH9: 0.0221 | DI9: 0.0227 | DJ9: 0.022 | DK9: 0.0226 | DL9: 0.0222 | DM9: 0.0236 | DN9: 0.0232 | DO9: 0.0233 | DP9: 0.0239 | DQ9: 0.0232 | DR9: 0.0235 | DS9: 0.0234 | DT9: 0.0191 | DU9: 0.0184 | DV9: 0.0188 | DW9: 0.0173 | DX9: 0.0177 | DY9: 0.0152 | DZ9: 0.0141 | EA9: 0.0141 | EB9: 0.0146 | EC9: 0.014 | ED9: 0.0144 | EE9: 0.0145 | EF9: 0.0142 | EG9: 0.0144 | EH9: 0.0139 | EI9: 0.0128 | EJ9: 0.0115 | EK9: 0.0111 | EL9: 0.0114 | EM9: 0.0115 | EN9: 0.0117 | EO9: 0.0117 | EP9: 0.0119 | EQ9: 0.012 | ER9: 0.0116 | ES9: 0.0113 | ET9: 0.0106 | EU9: 0.011 | EV9: 0.0114 | EW9: 0.0109 | EX9: 0.0109 | EY9: 0.0113 | EZ9: 0.0111 | FA9: 0.0117 | FB9: 0.0111 | FC9: 0.0112 | FD9: 0.0108 | FE9: 0.0114 | FF9: 0.0103 | FG9: 0.0104 | FH9: 0.0111 | FI9: 0.0115 | FJ9: 0.0115 | FK9: 0.0109 | FL9: 0.0109 | FM9: 0.0108 | FN9: 0.0102 | FO9: 0.0111 | FP9: 0.0106 | FQ9: 0.0103 | FR9: 0.0098 | FS9: 0.0103 | FT9: 0.0108 | FU9: 0.0108 | FV9: 0.0108 | FW9: 0.0106 | FX9: 0.01 | FY9: 0.0106 | FZ9: 0.0104 | GA9: 0.01 | GB9: 0.0096 | GC9: 0.0094 | GD9: 0.0076 | GE9: 0.0086 | GF9: 0.0085 | GG9: 0.0067 | GH9: 0.0035 | GI9: 0.0019 | GJ9: 0.0007 | GK9: 0.0005 | GL9: 0.0004 | GM9: 0.0004 | GN9: 0.0004 | GO9: 0.0004 | GP9: 0.0003 | GQ9: 0.0003 | GR9: 0.0003 | GS9: 0.0002 | GT9: 0.0002 | GU9: 0.0003 | GV9: 0.0003 | GW9: 0.0002 | GX9: 0.0003 | GY9: 0.0002 | GZ9: 0.0009 | HA9: 0.0057 | HB9: 0.0078 | HC9: 0.0116 | HD9: 0.0139 | HE9: 0.0223 | HF9: 0.0309 | HG9: 0.0376 | HH9: 0.0468 | HI9: 0.0511 | HJ9: 0.0542 | HK9: 0.0536 | HL9: 0.0547 | HM9: 0.0547 | HN9: 0.0541 | HO9: 0.0534 | HP9: 0.0532 | HQ9: 0.0519 | HR9: 0.0514 | HS9: 0.052 | HT9: 0.0529 | HU9: 0.0526 | HV9: 0.0522 | HW9: 0.0452 | HX9: 0.0421 | HY9: 0.0413 | HZ9: 0.0388 | IA9: 0.0407 | IB9: 0.0398 | IC9: 0.0397 | ID9: 0.0397 | IE9: 0.0397 | IF9: 0.0396 | IG9: 0.0409 | IH9: 0.0404 | II9: 0.041 | IJ9: 0.0408 | IK9: 0.0409 | IL9: 0.0397 | IM9: 0.04 | IN9: 0.0401 | IO9: 0.0416 | IP9: 0.0415 | IQ9: 0.0391 | IR9: 0.0381 | IS9: 0.0362 | IT9: 0.0357 | IU9: 0.0343 | IV9: 0.0325 | IW9: 0.0294 | IX9: 0.0267 | IY9: 0.0268 | IZ9: 0.027 | JA9: 0.0266 | JB9: 0.0253 | JC9: 0.0255 | JD9: 0.0265 | JE9: 0.0261
D10: powyżej 1 miesiąca do 3 miesięcy włącznie | E10: 8 | F10: M_7;AC:A,BCS:2240,BI:L22,BRS:S1,CT:PLN,DTM:R,F:M,IBC:N,MO:T07,RA:PL | G10: 0.0603 | H10: 0.0595 | I10: 0.0582 | J10: 0.0534 | K10: 0.0505 | L10: 0.0479 | M10: 0.0436 | N10: 0.0427 | O10: 0.0412 | P10: 0.0412 | Q10: 0.0416 | R10: 0.0409 | S10: 0.0402 | T10: 0.0381 | U10: 0.0373 | V10: 0.0372 | W10: 0.0373 | X10: 0.0377 | Y10: 0.0371 | Z10: 0.0372 | AA10: 0.0372 | AB10: 0.0371 | AC10: 0.0372 | AD10: 0.0372 | AE10: 0.0371 | AF10: 0.037 | AG10: 0.0376 | AH10: 0.0378 | AI10: 0.0398 | AJ10: 0.0408 | AK10: 0.0427 | AL10: 0.043 | AM10: 0.045 | AN10: 0.0456 | AO10: 0.0465 | AP10: 0.0499 | AQ10: 0.0502 | AR10: 0.0511 | AS10: 0.0543 | AT10: 0.0569 | AU10: 0.0579 | AV10: 0.0592 | AW10: 0.0593 | AX10: 0.053 | AY10: 0.0603 | AZ10: 0.0628 | BA10: 0.0647 | BB10: 0.0674 | BC10: 0.0598 | BD10: 0.0534 | BE10: 0.0503 | BF10: 0.0472 | BG10: 0.0464 | BH10: 0.0464 | BI10: 0.0435 | BJ10: 0.042 | BK10: 0.0416 | BL10: 0.0432 | BM10: 0.0436 | BN10: 0.0454 | BO10: 0.041 | BP10: 0.0408 | BQ10: 0.0393 | BR10: 0.0378 | BS10: 0.0377 | BT10: 0.0375 | BU10: 0.0377 | BV10: 0.038 | BW10: 0.0402 | BX10: 0.0387 | BY10: 0.0408 | BZ10: 0.0405 | CA10: 0.0395 | CB10: 0.0401 | CC10: 0.041 | CD10: 0.0419 | CE10: 0.0442 | CF10: 0.0479 | CG10: 0.0471 | CH10: 0.0502 | CI10: 0.0516 | CJ10: 0.0516 | CK10: 0.0545 | CL10: 0.0548 | CM10: 0.0521 | CN10: 0.0526 | CO10: 0.0507 | CP10: 0.0518 | CQ10: 0.0521 | CR10: 0.0549 | CS10: 0.0544 | CT10: 0.0532 | CU10: 0.0525 | CV10: 0.052 | CW10: 0.0492 | CX10: 0.046 | CY10: 0.0423 | CZ10: 0.0408 | DA10: 0.0357 | DB10: 0.0343 | DC10: 0.0307 | DD10: 0.0285 | DE10: 0.0265 | DF10: 0.0263 | DG10: 0.0267 | DH10: 0.0266 | DI10: 0.0268 | DJ10: 0.0275 | DK10: 0.0268 | DL10: 0.0272 | DM10: 0.0275 | DN10: 0.0276 | DO10: 0.028 | DP10: 0.0283 | DQ10: 0.0276 | DR10: 0.0271 | DS10: 0.0268 | DT10: 0.0229 | DU10: 0.0211 | DV10: 0.0213 | DW10: 0.0208 | DX10: 0.0206 | DY10: 0.0178 | DZ10: 0.0173 | EA10: 0.0172 | EB10: 0.0173 | EC10: 0.0172 | ED10: 0.0175 | EE10: 0.0177 | EF10: 0.0176 | EG10: 0.0179 | EH10: 0.0183 | EI10: 0.0163 | EJ10: 0.0153 | EK10: 0.0149 | EL10: 0.0144 | EM10: 0.0143 | EN10: 0.0148 | EO10: 0.0155 | EP10: 0.0153 | EQ10: 0.0156 | ER10: 0.0155 | ES10: 0.0155 | ET10: 0.0153 | EU10: 0.015 | EV10: 0.0151 | EW10: 0.0151 | EX10: 0.015 | EY10: 0.0152 | EZ10: 0.0152 | FA10: 0.0153 | FB10: 0.0155 | FC10: 0.0154 | FD10: 0.0153 | FE10: 0.0156 | FF10: 0.0151 | FG10: 0.015 | FH10: 0.0148 | FI10: 0.0149 | FJ10: 0.0148 | FK10: 0.0146 | FL10: 0.0147 | FM10: 0.0147 | FN10: 0.0147 | FO10: 0.0151 | FP10: 0.0143 | FQ10: 0.0145 | FR10: 0.0144 | FS10: 0.0144 | FT10: 0.0144 | FU10: 0.0143 | FV10: 0.014 | FW10: 0.0142 | FX10: 0.0139 | FY10: 0.0137 | FZ10: 0.0136 | GA10: 0.0137 | GB10: 0.0136 | GC10: 0.0135 | GD10: 0.0126 | GE10: 0.0125 | GF10: 0.0126 | GG10: 0.0104 | GH10: 0.0055 | GI10: 0.0034 | GJ10: 0.0012 | GK10: 0.0007 | GL10: 0.0006 | GM10: 0.0005 | GN10: 0.0005 | GO10: 0.0005 | GP10: 0.0007 | GQ10: 0.0006 | GR10: 0.0005 | GS10: 0.0005 | GT10: 0.0005 | GU10: 0.0005 | GV10: 0.0004 | GW10: 0.0004 | GX10: 0.0004 | GY10: 0.0004 | GZ10: 0.0014 | HA10: 0.0065 | HB10: 0.0081 | HC10: 0.0125 | HD10: 0.0155 | HE10: 0.0264 | HF10: 0.0378 | HG10: 0.0458 | HH10: 0.0536 | HI10: 0.0576 | HJ10: 0.0616 | HK10: 0.0621 | HL10: 0.062 | HM10: 0.0645 | HN10: 0.0599 | HO10: 0.0589 | HP10: 0.0594 | HQ10: 0.0569 | HR10: 0.0572 | HS10: 0.0568 | HT10: 0.0573 | HU10: 0.0568 | HV10: 0.0562 | HW10: 0.0492 | HX10: 0.0454 | HY10: 0.046 | HZ10: 0.0427 | IA10: 0.044 | IB10: 0.0457 | IC10: 0.0428 | ID10: 0.0449 | IE10: 0.0435 | IF10: 0.0437 | IG10: 0.045 | IH10: 0.0443 | II10: 0.0441 | IJ10: 0.0437 | IK10: 0.0441 | IL10: 0.0436 | IM10: 0.0433 | IN10: 0.0444 | IO10: 0.0452 | IP10: 0.0439 | IQ10: 0.0418 | IR10: 0.0406 | IS10: 0.04 | IT10: 0.0379 | IU10: 0.037 | IV10: 0.0349 | IW10: 0.0319 | IX10: 0.03 | IY10: 0.029 | IZ10: 0.0297 | JA10: 0.0287 | JB10: 0.0294 | JC10: 0.0292 | JD10: 0.0301 | JE10: 0.0298
D11: powyżej 3 miesięcy do 6 miesięcy włącznie | E11: 9 | F11: M_7;AC:A,BCS:2240,BI:L22,BRS:S1,CT:PLN,DTM:R,F:M,IBC:N,MO:T08,RA:PL | G11: 0.0602 | H11: 0.0594 | I11: 0.0563 | J11: 0.0514 | K11: 0.0477 | L11: 0.0465 | M11: 0.0422 | N11: 0.0415 | O11: 0.0401 | P11: 0.0403 | Q11: 0.0419 | R11: 0.0414 | S11: 0.0401 | T11: 0.0391 | U11: 0.0372 | V11: 0.0372 | W11: 0.0382 | X11: 0.0379 | Y11: 0.0381 | Z11: 0.0373 | AA11: 0.0371 | AB11: 0.0387 | AC11: 0.0382 | AD11: 0.0383 | AE11: 0.0383 | AF11: 0.0382 | AG11: 0.0387 | AH11: 0.0396 | AI11: 0.0397 | AJ11: 0.0408 | AK11: 0.0424 | AL11: 0.0451 | AM11: 0.0452 | AN11: 0.0463 | AO11: 0.0467 | AP11: 0.0505 | AQ11: 0.0501 | AR11: 0.051 | AS11: 0.0549 | AT11: 0.0564 | AU11: 0.0573 | AV11: 0.0598 | AW11: 0.0616 | AX11: 0.0603 | AY11: 0.0621 | AZ11: 0.0623 | BA11: 0.0711 | BB11: 0.0684 | BC11: 0.0608 | BD11: 0.0541 | BE11: 0.0508 | BF11: 0.0492 | BG11: 0.0531 | BH11: 0.0483 | BI11: 0.0476 | BJ11: 0.0472 | BK11: 0.0467 | BL11: 0.0481 | BM11: 0.0456 | BN11: 0.0481 | BO11: 0.0467 | BP11: 0.0439 | BQ11: 0.0435 | BR11: 0.0433 | BS11: 0.0408 | BT11: 0.0406 | BU11: 0.0416 | BV11: 0.0415 | BW11: 0.0425 | BX11: 0.0448 | BY11: 0.0431 | BZ11: 0.0435 | CA11: 0.0432 | CB11: 0.0443 | CC11: 0.0438 | CD11: 0.045 | CE11: 0.0473 | CF11: 0.0487 | CG11: 0.0503 | CH11: 0.0528 | CI11: 0.0544 | CJ11: 0.0553 | CK11: 0.0583 | CL11: 0.0572 | CM11: 0.0537 | CN11: 0.054 | CO11: 0.0538 | CP11: 0.0529 | CQ11: 0.0559 | CR11: 0.0549 | CS11: 0.0551 | CT11: 0.0548 | CU11: 0.055 | CV11: 0.0519 | CW11: 0.0494 | CX11: 0.0454 | CY11: 0.043 | CZ11: 0.0408 | DA11: 0.0362 | DB11: 0.0348 | DC11: 0.0304 | DD11: 0.0277 | DE11: 0.0279 | DF11: 0.0272 | DG11: 0.0276 | DH11: 0.0279 | DI11: 0.0283 | DJ11: 0.0291 | DK11: 0.0283 | DL11: 0.0284 | DM11: 0.0282 | DN11: 0.0287 | DO11: 0.0266 | DP11: 0.0296 | DQ11: 0.0287 | DR11: 0.0283 | DS11: 0.0278 | DT11: 0.025 | DU11: 0.0209 | DV11: 0.0225 | DW11: 0.0219 | DX11: 0.0216 | DY11: 0.0193 | DZ11: 0.0189 | EA11: 0.0181 | EB11: 0.0197 | EC11: 0.0195 | ED11: 0.0199 | EE11: 0.0191 | EF11: 0.0195 | EG11: 0.0202 | EH11: 0.019 | EI11: 0.0179 | EJ11: 0.0179 | EK11: 0.017 | EL11: 0.0172 | EM11: 0.0165 | EN11: 0.016 | EO11: 0.017 | EP11: 0.0171 | EQ11: 0.0168 | ER11: 0.0173 | ES11: 0.0172 | ET11: 0.0171 | EU11: 0.017 | EV11: 0.017 | EW11: 0.0167 | EX11: 0.0167 | EY11: 0.0169 | EZ11: 0.017 | FA11: 0.0172 | FB11: 0.0171 | FC11: 0.0174 | FD11: 0.0171 | FE11: 0.0172 | FF11: 0.0157 | FG11: 0.017 | FH11: 0.0169 | FI11: 0.0158 | FJ11: 0.0161 | FK11: 0.017 | FL11: 0.0171 | FM11: 0.0171 | FN11: 0.0169 | FO11: 0.016 | FP11: 0.0165 | FQ11: 0.0159 | FR11: 0.0165 | FS11: 0.0157 | FT11: 0.0163 | FU11: 0.0153 | FV11: 0.0155 | FW11: 0.0163 | FX11: 0.0152 | FY11: 0.0147 | FZ11: 0.0149 | GA11: 0.0156 | GB11: 0.0152 | GC11: 0.0149 | GD11: 0.0122 | GE11: 0.0138 | GF11: 0.0135 | GG11: 0.0116 | GH11: 0.0059 | GI11: 0.0042 | GJ11: 0.0012 | GK11: 0.001 | GL11: 0.0006 | GM11: 0.0006 | GN11: 0.0007 | GO11: 0.0007 | GP11: 0.0006 | GQ11: 0.0007 | GR11: 0.0006 | GS11: 0.0005 | GT11: 0.0005 | GU11: 0.0005 | GV11: 0.0005 | GW11: 0.0004 | GX11: 0.0004 | GY11: 0.0006 | GZ11: 0.0011 | HA11: 0.0064 | HB11: 0.0095 | HC11: 0.0133 | HD11: 0.0177 | HE11: 0.0274 | HF11: 0.0377 | HG11: 0.0489 | HH11: 0.0542 | HI11: 0.0554 | HJ11: 0.0587 | HK11: 0.061 | HL11: 0.0621 | HM11: 0.0653 | HN11: 0.0651 | HO11: 0.0605 | HP11: 0.0586 | HQ11: 0.0594 | HR11: 0.0559 | HS11: 0.057 | HT11: 0.0583 | HU11: 0.056 | HV11: 0.0528 | HW11: 0.048 | HX11: 0.0445 | HY11: 0.0438 | HZ11: 0.0443 | IA11: 0.0432 | IB11: 0.0462 | IC11: 0.0463 | ID11: 0.0436 | IE11: 0.0441 | IF11: 0.0448 | IG11: 0.0453 | IH11: 0.0436 | II11: 0.044 | IJ11: 0.0463 | IK11: 0.0435 | IL11: 0.0446 | IM11: 0.0418 | IN11: 0.0442 | IO11: 0.0453 | IP11: 0.042 | IQ11: 0.0377 | IR11: 0.0378 | IS11: 0.0356 | IT11: 0.0353 | IU11: 0.0352 | IV11: 0.0337 | IW11: 0.03 | IX11: 0.031 | IY11: 0.0294 | IZ11: 0.029 | JA11: 0.0307 | JB11: 0.0289 | JC11: 0.0275 | JD11: 0.028 | JE11: 0.0302
D12: powyżej 6 miesięcy do 1 roku włącznie | E12: 10 | F12: M_7;AC:A,BCS:2240,BI:L22,BRS:S1,CT:PLN,DTM:R,F:M,IBC:N,MO:T10,RA:PL | G12: 0.0555 | H12: 0.0513 | I12: 0.0506 | J12: 0.0481 | K12: 0.0479 | L12: 0.0444 | M12: 0.0405 | N12: 0.0424 | O12: 0.0372 | P12: 0.0407 | Q12: 0.0415 | R12: 0.0413 | S12: 0.0376 | T12: 0.0374 | U12: 0.0364 | V12: 0.0378 | W12: 0.0372 | X12: 0.0377 | Y12: 0.0371 | Z12: 0.0369 | AA12: 0.0374 | AB12: 0.0375 | AC12: 0.0376 | AD12: 0.0359 | AE12: 0.0383 | AF12: 0.0388 | AG12: 0.0389 | AH12: 0.0413 | AI12: 0.0376 | AJ12: 0.0405 | AK12: 0.0395 | AL12: 0.04 | AM12: 0.0406 | AN12: 0.0369 | AO12: 0.0443 | AP12: 0.0493 | AQ12: 0.0501 | AR12: 0.0488 | AS12: 0.0546 | AT12: 0.0523 | AU12: 0.0509 | AV12: 0.0542 | AW12: 0.054 | AX12: 0.0542 | AY12: 0.0528 | AZ12: 0.0596 | BA12: 0.0679 | BB12: 0.0665 | BC12: 0.0595 | BD12: 0.0564 | BE12: 0.0481 | BF12: 0.0463 | BG12: 0.0477 | BH12: 0.0484 | BI12: 0.0507 | BJ12: 0.0486 | BK12: 0.0485 | BL12: 0.0501 | BM12: 0.048 | BN12: 0.0471 | BO12: 0.0463 | BP12: 0.0462 | BQ12: 0.0447 | BR12: 0.0433 | BS12: 0.0419 | BT12: 0.0421 | BU12: 0.0439 | BV12: 0.0406 | BW12: 0.0425 | BX12: 0.0464 | BY12: 0.0441 | BZ12: 0.0443 | CA12: 0.0457 | CB12: 0.0467 | CC12: 0.0469 | CD12: 0.0449 | CE12: 0.0447 | CF12: np. | CG12: 0.0496 | CH12: 0.0483 | CI12: 0.0537 | CJ12: 0.051 | CK12: 0.054 | CL12: 0.0535 | CM12: 0.0534 | CN12: 0.0539 | CO12: 0.0516 | CP12: 0.0537 | CQ12: 0.0541 | CR12: 0.0523 | CS12: 0.054 | CT12: 0.0536 | CU12: 0.0526 | CV12: 0.0519 | CW12: 0.0476 | CX12: 0.0448 | CY12: 0.0428 | CZ12: 0.0384 | DA12: 0.0375 | DB12: 0.0336 | DC12: 0.0293 | DD12: 0.0279 | DE12: 0.0291 | DF12: 0.0283 | DG12: 0.0309 | DH12: 0.031 | DI12: 0.0308 | DJ12: 0.03 | DK12: 0.0306 | DL12: 0.0309 | DM12: 0.031 | DN12: 0.032 | DO12: 0.032 | DP12: 0.0279 | DQ12: 0.0288 | DR12: 0.0268 | DS12: 0.0273 | DT12: 0.022 | DU12: 0.023 | DV12: 0.0231 | DW12: 0.0202 | DX12: 0.0209 | DY12: 0.0182 | DZ12: 0.0156 | EA12: 0.0174 | EB12: 0.0192 | EC12: 0.0183 | ED12: 0.0188 | EE12: 0.0185 | EF12: 0.0199 | EG12: 0.0205 | EH12: 0.019 | EI12: 0.0188 | EJ12: 0.0181 | EK12: 0.0179 | EL12: 0.0179 | EM12: 0.0179 | EN12: 0.0174 | EO12: 0.0181 | EP12: 0.0178 | EQ12: 0.018 | ER12: 0.0172 | ES12: 0.0187 | ET12: 0.0181 | EU12: 0.0177 | EV12: 0.017 | EW12: 0.018 | EX12: 0.0173 | EY12: 0.0165 | EZ12: 0.0174 | FA12: 0.0154 | FB12: 0.0177 | FC12: 0.0172 | FD12: 0.0164 | FE12: 0.0172 | FF12: 0.0174 | FG12: 0.0169 | FH12: 0.0165 | FI12: 0.0179 | FJ12: 0.0173 | FK12: 0.0169 | FL12: 0.0174 | FM12: 0.0175 | FN12: 0.019 | FO12: 0.0186 | FP12: 0.017 | FQ12: 0.0172 | FR12: 0.017 | FS12: 0.0157 | FT12: 0.0163 | FU12: 0.0165 | FV12: 0.0137 | FW12: 0.0161 | FX12: 0.0148 | FY12: 0.0155 | FZ12: 0.0155 | GA12: 0.0162 | GB12: 0.0149 | GC12: 0.015 | GD12: 0.0145 | GE12: 0.0145 | GF12: 0.0131 | GG12: 0.0116 | GH12: 0.0049 | GI12: 0.0046 | GJ12: 0.0017 | GK12: 0.0013 | GL12: 0.0008 | GM12: 0.0007 | GN12: 0.0006 | GO12: 0.0005 | GP12: 0.0008 | GQ12: 0.0006 | GR12: 0.0006 | GS12: 0.0006 | GT12: 0.0004 | GU12: 0.0004 | GV12: 0.0005 | GW12: 0.0005 | GX12: 0.0003 | GY12: 0.0004 | GZ12: 0.0017 | HA12: 0.0033 | HB12: 0.0115 | HC12: 0.0107 | HD12: 0.016 | HE12: 0.029 | HF12: 0.0271 | HG12: 0.0382 | HH12: 0.0511 | HI12: 0.0441 | HJ12: 0.0477 | HK12: 0.0413 | HL12: 0.0507 | HM12: 0.0521 | HN12: 0.0593 | HO12: 0.0604 | HP12: 0.0568 | HQ12: 0.0593 | HR12: 0.0554 | HS12: 0.0567 | HT12: 0.054 | HU12: 0.0538 | HV12: 0.0519 | HW12: 0.0434 | HX12: 0.0421 | HY12: 0.0412 | HZ12: 0.0394 | IA12: 0.0417 | IB12: 0.0427 | IC12: 0.0433 | ID12: 0.0424 | IE12: 0.0436 | IF12: 0.0438 | IG12: 0.0435 | IH12: 0.0414 | II12: 0.0388 | IJ12: 0.0431 | IK12: 0.0417 | IL12: 0.0395 | IM12: 0.0419 | IN12: 0.0436 | IO12: 0.0419 | IP12: 0.0412 | IQ12: 0.034 | IR12: 0.0322 | IS12: 0.0339 | IT12: 0.0337 | IU12: 0.0353 | IV12: 0.0292 | IW12: 0.0295 | IX12: 0.0244 | IY12: 0.0256 | IZ12: 0.0269 | JA12: 0.0281 | JB12: 0.0268 | JC12: 0.0282 | JD12: 0.0295 | JE12: 0.0269
D13: powyżej 1 roku | E13: 11 | F13: M_7;AC:A,BCS:2240,BI:L22,BRS:S1,CT:PLN,DTM:R,F:M,IBC:N,MO:K,RA:PL | G13: 0.0537 | H13: 0.0512 | I13: 0.0482 | J13: 0.0492 | K13: 0.0473 | L13: 0.0418 | M13: 0.0403 | N13: 0.0381 | O13: 0.0384 | P13: 0.0327 | Q13: 0.0405 | R13: 0.04 | S13: 0.0379 | T13: 0.0331 | U13: 0.0312 | V13: 0.0242 | W13: 0.0257 | X13: 0.0332 | Y13: 0.0363 | Z13: 0.0352 | AA13: 0.0376 | AB13: 0.0332 | AC13: 0.0353 | AD13: 0.0176 | AE13: 0.0376 | AF13: 0.0108 | AG13: 0.038 | AH13: 0.0158 | AI13: 0.0374 | AJ13: 0.038 | AK13: 0.0386 | AL13: 0.0416 | AM13: 0.0414 | AN13: 0.0435 | AO13: 0.0201 | AP13: 0.0188 | AQ13: 0.0472 | AR13: 0.0481 | AS13: 0.0245 | AT13: 0.0329 | AU13: 0.0311 | AV13: 0.0275 | AW13: 0.0536 | AX13: 0.0324 | AY13: 0.0529 | AZ13: 0.0567 | BA13: 0.0609 | BB13: 0.0655 | BC13: 0.049 | BD13: 0.0468 | BE13: 0.0383 | BF13: 0.0445 | BG13: 0.0325 | BH13: 0.0402 | BI13: 0.0438 | BJ13: 0.0369 | BK13: 0.0344 | BL13: 0.0407 | BM13: 0.0372 | BN13: 0.0461 | BO13: 0.0412 | BP13: 0.047 | BQ13: 0.033 | BR13: 0.0421 | BS13: 0.0432 | BT13: 0.0483 | BU13: 0.0447 | BV13: 0.0475 | BW13: 0.038 | BX13: 0.0493 | BY13: 0.0442 | BZ13: 0.0421 | CA13: 0.0463 | CB13: 0.0457 | CC13: 0.0462 | CD13: np. | CE13: 0.0465 | CF13: 0.045 | CG13: 0.0462 | CH13: 0.0458 | CI13: 0.0426 | CJ13: 0.0547 | CK13: 0.0467 | CL13: 0.0513 | CM13: 0.044 | CN13: 0.0452 | CO13: 0.0482 | CP13: 0.0437 | CQ13: 0.0559 | CR13: 0.0556 | CS13: 0.0532 | CT13: 0.0503 | CU13: np. | CV13: 0.05 | CW13: 0.0416 | CX13: 0.041 | CY13: 0.0381 | CZ13: 0.0374 | DA13: 0.0335 | DB13: 0.0318 | DC13: 0.0298 | DD13: np. | DE13: np. | DF13: 0.0266 | DG13: 0.0255 | DH13: 0.0254 | DI13: np. | DJ13: 0.0265 | DK13: 0.0256 | DL13: 0.0246 | DM13: 0.0283 | DN13: 0.0224 | DO13: 0.0275 | DP13: 0.0245 | DQ13: 0.0225 | DR13: 0.0225 | DS13: 0.0208 | DT13: 0.0179 | DU13: 0.0161 | DV13: 0.0177 | DW13: 0.0165 | DX13: 0.0168 | DY13: 0.0173 | DZ13: 0.0147 | EA13: 0.0147 | EB13: 0.0169 | EC13: 0.0126 | ED13: 0.014 | EE13: 0.012 | EF13: 0.0116 | EG13: 0.0128 | EH13: 0.0174 | EI13: 0.0145 | EJ13: 0.0147 | EK13: 0.014 | EL13: 0.0149 | EM13: 0.0175 | EN13: 0.0135 | EO13: 0.0182 | EP13: 0.0144 | EQ13: np. | ER13: 0.0179 | ES13: 0.0175 | ET13: 0.0161 | EU13: 0.0162 | EV13: 0.0163 | EW13: np. | EX13: np. | EY13: np. | EZ13: np. | FA13: np. | FB13: np. | FC13: np. | FD13: np. | FE13: 0.0146 | FF13: 0.015 | FG13: 0.0149 | FH13: 0.0106 | FI13: 0.0131 | FJ13: 0.0123 | FK13: 0.0131 | FL13: 0.0129 | FM13: 0.0155 | FN13: 0.0109 | FO13: 0.014 | FP13: 0.0134 | FQ13: 0.0128 | FR13: 0.016 | FS13: 0.0173 | FT13: 0.0135 | FU13: 0.0109 | FV13: 0.0128 | FW13: 0.0151 | FX13: 0.0128 | FY13: 0.011 | FZ13: 0.0126 | GA13: 0.0099 | GB13: 0.01 | GC13: 0.0105 | GD13: 0.0108 | GE13: 0.0116 | GF13: 0.007 | GG13: np. | GH13: 0.0037 | GI13: 0.0024 | GJ13: 0.0005 | GK13: 0.001 | GL13: 0.0005 | GM13: 0.0004 | GN13: 0.0016 | GO13: 0.0004 | GP13: 0.0005 | GQ13: np. | GR13: 0.0003 | GS13: 0.0003 | GT13: np. | GU13: 0.0006 | GV13: 0.0007 | GW13: 0.0006 | GX13: np. | GY13: 0.0002 | GZ13: 0.0003 | HA13: 0.0009 | HB13: 0.0067 | HC13: 0.0081 | HD13: 0.0071 | HE13: 0.0081 | HF13: 0.0223 | HG13: 0.0198 | HH13: 0.0236 | HI13: 0.0433 | HJ13: 0.0197 | HK13: 0.0397 | HL13: 0.0281 | HM13: 0.0435 | HN13: 0.0451 | HO13: 0.0525 | HP13: 0.0291 | HQ13: 0.0529 | HR13: 0.0501 | HS13: 0.0476 | HT13: 0.0483 | HU13: 0.0366 | HV13: np. | HW13: 0.0281 | HX13: 0.0393 | HY13: 0.0314 | HZ13: 0.0363 | IA13: 0.0339 | IB13: 0.032 | IC13: 0.0384 | ID13: 0.0362 | IE13: 0.0408 | IF13: 0.0403 | IG13: 0.0398 | IH13: 0.0332 | II13: 0.0344 | IJ13: 0.0294 | IK13: 0.0263 | IL13: 0.0336 | IM13: 0.0345 | IN13: 0.0268 | IO13: 0.0314 | IP13: 0.028 | IQ13: 0.0246 | IR13: 0.0284 | IS13: 0.0295 | IT13: 0.0294 | IU13: 0.0242 | IV13: 0.0288 | IW13: 0.0255 | IX13: 0.021 | IY13: 0.028 | IZ13: 0.0279 | JA13: 0.0222 | JB13: 0.0264 | JC13: 0.0107 | JD13: 0.0322 | JE13: 0.0262
D14: ogółem | E14: 12 | F14: M_7;AC:A,BCS:2240,BI:L22,BRS:S1,CT:PLN,DTM:R,F:M,IBC:N,MO:A,RA:PL | G14: 0.0568 | H14: 0.0552 | I14: 0.0572 | J14: 0.0524 | K14: 0.0483 | L14: 0.0461 | M14: 0.0434 | N14: 0.0417 | O14: 0.0404 | P14: 0.0403 | Q14: 0.04 | R14: 0.0378 | S14: 0.0391 | T14: 0.0374 | U14: 0.0359 | V14: 0.0357 | W14: 0.036 | X14: 0.0353 | Y14: 0.0359 | Z14: 0.0357 | AA14: 0.0353 | AB14: 0.036 | AC14: 0.0353 | AD14: 0.0349 | AE14: 0.0355 | AF14: 0.0358 | AG14: 0.0358 | AH14: 0.0354 | AI14: 0.0385 | AJ14: 0.0395 | AK14: 0.0412 | AL14: 0.041 | AM14: 0.0424 | AN14: 0.0451 | AO14: 0.0458 | AP14: 0.0423 | AQ14: 0.0474 | AR14: 0.0497 | AS14: 0.053 | AT14: 0.0552 | AU14: 0.0539 | AV14: 0.0556 | AW14: 0.0561 | AX14: 0.0558 | AY14: 0.0558 | AZ14: 0.057 | BA14: 0.0554 | BB14: 0.056 | BC14: 0.0488 | BD14: 0.0402 | BE14: 0.0343 | BF14: 0.0333 | BG14: 0.0347 | BH14: 0.0329 | BI14: 0.0308 | BJ14: 0.0298 | BK14: 0.0302 | BL14: 0.0301 | BM14: 0.0308 | BN14: 0.0299 | BO14: 0.0292 | BP14: 0.0293 | BQ14: 0.0294 | BR14: 0.0297 | BS14: 0.0305 | BT14: 0.0305 | BU14: 0.0292 | BV14: 0.0302 | BW14: 0.0309 | BX14: 0.0311 | BY14: 0.0305 | BZ14: 0.0305 | CA14: 0.0301 | CB14: 0.0317 | CC14: 0.0336 | CD14: 0.0346 | CE14: 0.0351 | CF14: 0.0399 | CG14: 0.0407 | CH14: 0.042 | CI14: 0.0427 | CJ14: 0.0421 | CK14: 0.0444 | CL14: 0.0433 | CM14: 0.042 | CN14: 0.0417 | CO14: 0.0424 | CP14: 0.043 | CQ14: 0.0444 | CR14: 0.0456 | CS14: 0.0462 | CT14: 0.0455 | CU14: 0.0462 | CV14: 0.0446 | CW14: 0.0432 | CX14: 0.0395 | CY14: 0.0366 | CZ14: 0.0352 | DA14: 0.0312 | DB14: 0.0295 | DC14: 0.0272 | DD14: 0.0248 | DE14: 0.0229 | DF14: 0.0228 | DG14: 0.0232 | DH14: 0.0232 | DI14: 0.0237 | DJ14: 0.0232 | DK14: 0.0236 | DL14: 0.0233 | DM14: 0.0246 | DN14: 0.0242 | DO14: 0.0243 | DP14: 0.0249 | DQ14: 0.0244 | DR14: 0.0243 | DS14: 0.0241 | DT14: 0.02 | DU14: 0.019 | DV14: 0.0192 | DW14: 0.0181 | DX14: 0.0183 | DY14: 0.0158 | DZ14: 0.0149 | EA14: 0.0149 | EB14: 0.0153 | EC14: 0.0148 | ED14: 0.0153 | EE14: 0.0153 | EF14: 0.015 | EG14: 0.0152 | EH14: 0.0149 | EI14: 0.0136 | EJ14: 0.0124 | EK14: 0.0121 | EL14: 0.0123 | EM14: 0.0123 | EN14: 0.0125 | EO14: 0.0129 | EP14: 0.0129 | EQ14: 0.0131 | ER14: 0.0129 | ES14: 0.0126 | ET14: 0.012 | EU14: 0.0123 | EV14: 0.0123 | EW14: 0.0122 | EX14: 0.0121 | EY14: 0.0125 | EZ14: 0.0124 | FA14: 0.013 | FB14: 0.0124 | FC14: 0.0126 | FD14: 0.0121 | FE14: 0.0124 | FF14: 0.0116 | FG14: 0.012 | FH14: 0.0122 | FI14: 0.0126 | FJ14: 0.0125 | FK14: 0.012 | FL14: 0.0122 | FM14: 0.0123 | FN14: 0.0117 | FO14: 0.0124 | FP14: 0.0119 | FQ14: 0.0115 | FR14: 0.0111 | FS14: 0.0118 | FT14: 0.012 | FU14: 0.0119 | FV14: 0.0118 | FW14: 0.0117 | FX14: 0.0112 | FY14: 0.0116 | FZ14: 0.0113 | GA14: 0.0112 | GB14: 0.0108 | GC14: 0.0105 | GD14: 0.0088 | GE14: 0.0099 | GF14: 0.0097 | GG14: 0.0077 | GH14: 0.0041 | GI14: 0.0025 | GJ14: 0.0009 | GK14: 0.0007 | GL14: 0.0005 | GM14: 0.0005 | GN14: 0.0005 | GO14: 0.0004 | GP14: 0.0005 | GQ14: 0.0005 | GR14: 0.0004 | GS14: 0.0003 | GT14: 0.0003 | GU14: 0.0004 | GV14: 0.0004 | GW14: 0.0003 | GX14: 0.0004 | GY14: 0.0004 | GZ14: 0.0011 | HA14: 0.0059 | HB14: 0.0081 | HC14: 0.012 | HD14: 0.0145 | HE14: 0.0231 | HF14: 0.0325 | HG14: 0.0405 | HH14: 0.0482 | HI14: 0.053 | HJ14: 0.0564 | HK14: 0.0558 | HL14: 0.0566 | HM14: 0.057 | HN14: 0.0554 | HO14: 0.055 | HP14: 0.0541 | HQ14: 0.0531 | HR14: 0.0527 | HS14: 0.0531 | HT14: 0.0538 | HU14: 0.0536 | HV14: 0.053 | HW14: 0.0459 | HX14: 0.0428 | HY14: 0.0422 | HZ14: 0.0396 | IA14: 0.0414 | IB14: 0.0409 | IC14: 0.0404 | ID14: 0.0407 | IE14: 0.0404 | IF14: 0.0408 | IG14: 0.0418 | IH14: 0.0411 | II14: 0.0415 | IJ14: 0.0415 | IK14: 0.0414 | IL14: 0.0404 | IM14: 0.0406 | IN14: 0.0408 | IO14: 0.0423 | IP14: 0.0419 | IQ14: 0.0395 | IR14: 0.0385 | IS14: 0.037 | IT14: 0.0361 | IU14: 0.0348 | IV14: 0.0329 | IW14: 0.0299 | IX14: 0.0273 | IY14: 0.0272 | IZ14: 0.0274 | JA14: 0.0271 | JB14: 0.0262 | JC14: 0.0262 | JD14: 0.0271 | JE14: 0.027
B15: ogółem | E15: 13 | F15: M_7;AC:A,BCS:2230,BI:L22,BRS:S1,CT:PLN,DTM:R,F:M,IBC:N,MO:A,RA:PL | G15: 0.0557 | H15: 0.0542 | I15: 0.0555 | J15: 0.051 | K15: 0.0473 | L15: 0.0453 | M15: 0.0424 | N15: 0.0409 | O15: 0.0396 | P15: 0.0392 | Q15: 0.0391 | R15: 0.0373 | S15: 0.0383 | T15: 0.0367 | U15: 0.0351 | V15: 0.0351 | W15: 0.0351 | X15: 0.0349 | Y15: 0.0353 | Z15: 0.0351 | AA15: 0.0348 | AB15: 0.0354 | AC15: 0.0348 | AD15: 0.0345 | AE15: 0.0351 | AF15: 0.0353 | AG15: 0.0354 | AH15: 0.035 | AI15: 0.0378 | AJ15: 0.0387 | AK15: 0.0405 | AL15: 0.0404 | AM15: 0.0418 | AN15: 0.044 | AO15: 0.0447 | AP15: 0.0422 | AQ15: 0.0464 | AR15: 0.049 | AS15: 0.0519 | AT15: 0.0538 | AU15: 0.0529 | AV15: 0.0545 | AW15: 0.0548 | AX15: 0.0552 | AY15: 0.0567 | AZ15: 0.0585 | BA15: 0.0575 | BB15: 0.0585 | BC15: 0.0519 | BD15: 0.0434 | BE15: 0.0382 | BF15: 0.0361 | BG15: 0.0372 | BH15: 0.0354 | BI15: 0.0336 | BJ15: 0.0328 | BK15: 0.033 | BL15: 0.0329 | BM15: 0.0332 | BN15: 0.0317 | BO15: 0.0312 | BP15: 0.0311 | BQ15: 0.0313 | BR15: 0.0316 | BS15: 0.0319 | BT15: 0.0316 | BU15: 0.0304 | BV15: 0.031 | BW15: 0.0317 | BX15: 0.0318 | BY15: 0.0313 | BZ15: 0.0312 | CA15: 0.0309 | CB15: 0.0325 | CC15: 0.0343 | CD15: 0.0352 | CE15: 0.0356 | CF15: 0.0401 | CG15: 0.041 | CH15: 0.0423 | CI15: 0.0429 | CJ15: 0.0427 | CK15: 0.0448 | CL15: 0.0443 | CM15: 0.0435 | CN15: 0.0429 | CO15: 0.0432 | CP15: 0.0438 | CQ15: 0.0451 | CR15: 0.0466 | CS15: 0.047 | CT15: 0.0462 | CU15: 0.0467 | CV15: 0.0455 | CW15: 0.0436 | CX15: 0.0401 | CY15: 0.0374 | CZ15: 0.0358 | DA15: 0.0318 | DB15: 0.0298 | DC15: 0.0274 | DD15: 0.025 | DE15: 0.0233 | DF15: 0.0231 | DG15: 0.0236 | DH15: 0.0238 | DI15: 0.0242 | DJ15: 0.0238 | DK15: 0.0241 | DL15: 0.024 | DM15: 0.025 | DN15: 0.0247 | DO15: 0.0248 | DP15: 0.0252 | DQ15: 0.0248 | DR15: 0.025 | DS15: 0.025 | DT15: 0.0211 | DU15: 0.0197 | DV15: 0.0202 | DW15: 0.0193 | DX15: 0.0197 | DY15: 0.0173 | DZ15: 0.0162 | EA15: 0.0158 | EB15: 0.0159 | EC15: 0.0157 | ED15: 0.0161 | EE15: 0.0159 | EF15: 0.0158 | EG15: 0.016 | EH15: 0.0157 | EI15: 0.0149 | EJ15: 0.0141 | EK15: 0.0136 | EL15: 0.0136 | EM15: 0.0135 | EN15: 0.0135 | EO15: 0.0145 | EP15: 0.0142 | EQ15: 0.0143 | ER15: 0.0142 | ES15: 0.0138 | ET15: 0.0131 | EU15: 0.0133 | EV15: 0.0134 | EW15: 0.0132 | EX15: 0.0129 | EY15: 0.0131 | EZ15: 0.0129 | FA15: 0.0136 | FB15: 0.0134 | FC15: 0.0133 | FD15: 0.0131 | FE15: 0.0135 | FF15: 0.0129 | FG15: 0.0135 | FH15: 0.0134 | FI15: 0.0136 | FJ15: 0.0136 | FK15: 0.0135 | FL15: 0.0138 | FM15: 0.0138 | FN15: 0.0134 | FO15: 0.0141 | FP15: 0.0136 | FQ15: 0.0143 | FR15: 0.0139 | FS15: 0.014 | FT15: 0.0141 | FU15: 0.0135 | FV15: 0.0133 | FW15: 0.0131 | FX15: 0.0123 | FY15: 0.0126 | FZ15: 0.0121 | GA15: 0.0119 | GB15: 0.0118 | GC15: 0.0115 | GD15: 0.01 | GE15: 0.0109 | GF15: 0.0105 | GG15: 0.0093 | GH15: 0.0057 | GI15: 0.0037 | GJ15: 0.0024 | GK15: 0.0019 | GL15: 0.0018 | GM15: 0.0027 | GN15: 0.0024 | GO15: 0.0024 | GP15: 0.0024 | GQ15: 0.0023 | GR15: 0.0015 | GS15: 0.001 | GT15: 0.001 | GU15: 0.0011 | GV15: 0.0012 | GW15: 0.0012 | GX15: 0.0013 | GY15: 0.0015 | GZ15: 0.0021 | HA15: 0.0055 | HB15: 0.0078 | HC15: 0.0114 | HD15: 0.0137 | HE15: 0.0213 | HF15: 0.0295 | HG15: 0.0383 | HH15: 0.0472 | HI15: 0.0517 | HJ15: 0.0551 | HK15: 0.0557 | HL15: 0.0566 | HM15: 0.0581 | HN15: 0.0572 | HO15: 0.0568 | HP15: 0.0553 | HQ15: 0.0544 | HR15: 0.0539 | HS15: 0.0542 | HT15: 0.0549 | HU15: 0.0541 | HV15: 0.0529 | HW15: 0.047 | HX15: 0.0437 | HY15: 0.043 | HZ15: 0.0409 | IA15: 0.0423 | IB15: 0.0418 | IC15: 0.0412 | ID15: 0.0411 | IE15: 0.0407 | IF15: 0.041 | IG15: 0.0417 | IH15: 0.041 | II15: 0.0413 | IJ15: 0.0411 | IK15: 0.0409 | IL15: 0.0402 | IM15: 0.0406 | IN15: 0.0407 | IO15: 0.0418 | IP15: 0.0415 | IQ15: 0.0395 | IR15: 0.0384 | IS15: 0.0373 | IT15: 0.0364 | IU15: 0.0351 | IV15: 0.0336 | IW15: 0.0312 | IX15: 0.0288 | IY15: 0.0288 | IZ15: 0.0287 | JA15: 0.028 | JB15: 0.0272 | JC15: 0.0271 | JD15: 0.0277 | JE15: 0.0278
A16: Kredyty i inne należności w PLN | B16: Gospodarstwa domowe i instytucje niekomercyjne działające na rzecz gospodarstw domowych | C16: Kredyty na cele konsumpcyjne (bez kredytów o charakterze bieżącym) | D16: stopa zmienna i stała do 3 miesięcy włącznie | E16: 14 | F16: M_7;AC:A,BCS:2250,BI:A2B,BRS:S1,CT:PLN,DTM:R,F:M,IBC:N,MO:D,RA:PL | G16: 0.1622 | H16: 0.1474 | I16: 0.1466 | J16: 0.1299 | K16: 0.1444 | L16: 0.1459 | M16: 0.1394 | N16: 0.1424 | O16: 0.1413 | P16: 0.1441 | Q16: 0.1479 | R16: 0.1415 | S16: 0.1414 | T16: 0.1425 | U16: 0.1472 | V16: 0.149 | W16: 0.1499 | X16: 0.1478 | Y16: 0.1345 | Z16: 0.1346 | AA16: 0.134 | AB16: 0.147 | AC16: 0.1423 | AD16: 0.1437 | AE16: 0.1562 | AF16: 0.1459 | AG16: 0.1463 | AH16: 0.1414 | AI16: 0.1436 | AJ16: 0.1393 | AK16: 0.1439 | AL16: 0.1442 | AM16: 0.1447 | AN16: 0.1488 | AO16: 0.1491 | AP16: 0.1479 | AQ16: 0.1507 | AR16: 0.1553 | AS16: 0.1604 | AT16: 0.1648 | AU16: 0.168 | AV16: 0.1701 | AW16: 0.1728 | AX16: 0.1736 | AY16: 0.1745 | AZ16: 0.1759 | BA16: 0.1684 | BB16: 0.1643 | BC16: 0.1698 | BD16: 0.164 | BE16: 0.1679 | BF16: 0.1693 | BG16: 0.1672 | BH16: 0.1683 | BI16: 0.1719 | BJ16: 0.1716 | BK16: 0.1697 | BL16: 0.164 | BM16: 0.165 | BN16: 0.1636 | BO16: 0.1607 | BP16: 0.1608 | BQ16: 0.162 | BR16: 0.1603 | BS16: 0.1617 | BT16: 0.1609 | BU16: 0.156 | BV16: 0.1551 | BW16: 0.1517 | BX16: 0.1477 | BY16: 0.149 | BZ16: 0.15 | CA16: 0.1508 | CB16: 0.1543 | CC16: 0.1549 | CD16: 0.1571 | CE16: 0.1589 | CF16: 0.1572 | CG16: 0.1535 | CH16: 0.1556 | CI16: 0.153 | CJ16: 0.1546 | CK16: 0.1527 | CL16: 0.1494 | CM16: 0.1556 | CN16: 0.152 | CO16: 0.1539 | CP16: 0.1548 | CQ16: 0.1523 | CR16: 0.1332 | CS16: 0.1517 | CT16: 0.1585 | CU16: 0.1574 | CV16: 0.1634 | CW16: 0.1645 | CX16: 0.1602 | CY16: 0.1603 | CZ16: 0.1506 | DA16: 0.1606 | DB16: 0.1471 | DC16: 0.1578 | DD16: 0.1427 | DE16: 0.1489 | DF16: 0.1463 | DG16: 0.1424 | DH16: 0.1419 | DI16: 0.1401 | DJ16: 0.1367 | DK16: 0.1385 | DL16: 0.1377 | DM16: 0.1393 | DN16: 0.1374 | DO16: 0.1379 | DP16: 0.1373 | DQ16: 0.1367 | DR16: 0.1333 | DS16: 0.1293 | DT16: 0.1144 | DU16: 0.11 | DV16: 0.1065 | DW16: 0.1075 | DX16: 0.1036 | DY16: 0.0929 | DZ16: 0.0909 | EA16: 0.0911 | EB16: 0.0901 | EC16: 0.0921 | ED16: 0.091 | EE16: 0.0883 | EF16: 0.0889 | EG16: 0.0881 | EH16: 0.0904 | EI16: 0.0913 | EJ16: 0.0894 | EK16: 0.0891 | EL16: 0.0878 | EM16: 0.088 | EN16: 0.087 | EO16: 0.0869 | EP16: 0.0884 | EQ16: 0.0864 | ER16: 0.0867 | ES16: 0.0862 | ET16: 0.0826 | EU16: 0.0851 | EV16: 0.084 | EW16: 0.0834 | EX16: 0.0841 | EY16: 0.0854 | EZ16: 0.0843 | FA16: 0.0855 | FB16: 0.086 | FC16: 0.0849 | FD16: 0.0851 | FE16: 0.0851 | FF16: 0.084 | FG16: 0.0851 | FH16: 0.0859 | FI16: 0.0853 | FJ16: 0.0855 | FK16: 0.086 | FL16: 0.0864 | FM16: 0.0863 | FN16: 0.0857 | FO16: 0.0858 | FP16: 0.0842 | FQ16: 0.0833 | FR16: 0.0852 | FS16: 0.087 | FT16: 0.0867 | FU16: 0.0874 | FV16: 0.0867 | FW16: 0.0864 | FX16: 0.0868 | FY16: 0.0878 | FZ16: 0.0876 | GA16: 0.0869 | GB16: 0.0878 | GC16: 0.0881 | GD16: 0.0874 | GE16: 0.0882 | GF16: 0.0886 | GG16: 0.086 | GH16: 0.0773 | GI16: 0.0744 | GJ16: 0.071 | GK16: 0.0713 | GL16: 0.0715 | GM16: 0.0715 | GN16: 0.0718 | GO16: 0.0711 | GP16: 0.0709 | GQ16: 0.0711 | GR16: 0.0711 | GS16: 0.0709 | GT16: 0.0708 | GU16: 0.0711 | GV16: 0.071 | GW16: 0.071 | GX16: 0.071 | GY16: 0.0708 | GZ16: 0.075 | HA16: 0.0823 | HB16: 0.0887 | HC16: 0.0962 | HD16: 0.0988 | HE16: 0.1032 | HF16: 0.1064 | HG16: 0.1119 | HH16: 0.1169 | HI16: 0.1208 | HJ16: 0.1237 | HK16: 0.1262 | HL16: 0.1255 | HM16: 0.1264 | HN16: 0.1297 | HO16: 0.1299 | HP16: 0.1305 | HQ16: 0.1321 | HR16: 0.1329 | HS16: 0.133 | HT16: 0.1324 | HU16: 0.1303 | HV16: 0.1311 | HW16: 0.1304 | HX16: 0.1301 | HY16: 0.1303 | HZ16: 0.1309 | IA16: 0.1272 | IB16: 0.1251 | IC16: 0.1246 | ID16: 0.1238 | IE16: 0.1252 | IF16: 0.1249 | IG16: 0.1444 | IH16: 0.1368 | II16: 0.1333 | IJ16: 0.1326 | IK16: 0.1287 | IL16: 0.1255 | IM16: 0.1292 | IN16: 0.1289 | IO16: 0.1276 | IP16: 0.127 | IQ16: 0.1269 | IR16: 0.1264 | IS16: 0.1198 | IT16: 0.1186 | IU16: 0.119 | IV16: 0.1177 | IW16: 0.1113 | IX16: 0.1086 | IY16: 0.1108 | IZ16: 0.1102 | JA16: 0.1087 | JB16: 0.1077 | JC16: 0.1081 | JD16: 0.1061 | JE16: 0.1059
